Workbook

Sheet 2020a
A1: RSUD ULIN Electrical Load Consumption During Special Holidays (Year 2020)
A3: Category | B3: Special Holiday | C3: Day / Date | D3: Day | I3: WDMAX | J3: LDMAX
D4: H-4 (Wh) | E4: H-3 (Wh) | F4: H-2 (Wh) | G4: H-1 (Wh) | H4: H (Wh)
A5: General Holidays | B5: 1. New Year | C5: Wednesday, Jan 01 | D5: 21584538 | E5: 22686539 | F5: 23612437 | G5: 26977415 | H5: 22567256 | I5: =(D5+E5+F5+G5)/4 -> 23715232 | J5: =((H5-I5)/I5)*100 -> -4.8406691
B6: 2. Independence Day | C6: Monday, Aug 17 | D6: 25800705 | E6: 24137737 | F6: 23092416 | G6: 21587126 | H6: 23420438 | I6: =(D6+E6+F6+G6)/4 -> 23654496 | J6: =((H6-I6)/I6)*100 -> -0.98948546
A7: Islamic Holidays | B7: 1. Idul Adha | C7: Friday, Jul 31 | D7: 23826316 | E7: 20324142 | F7: 22423342 | G7: 21423342 | H7: 21625342 | I7: =(D7+E7+F7+G7)/4 -> 21999285 | J7: =((H7-I7)/I7)*100 -> -1.6997987
B8: 2. Islamic New Year | C8: Thursday, Aug 20 | D8: 22587125 | E8: 23998476 | F8: 22757125 | G8: 23689126 | H8: 23812488 | I8: =(D8+E8+F8+G8)/4 -> 23257963 | J8: =((H8-I8)/I8)*100 -> 2.3842395
B9: 3. Maulid | C9: Thursday, Oct 29 | D9: 26102310 | E9: 26567257 | F9: 25763257 | G9: 26363240 | H9: 26978630 | I9: =(D9+E9+F9+G9)/4 -> 26199016 | J9: =((H9-I9)/I9)*100 -> 2.9757394
B10: 4. Isra Mi'raj | C10: Sunday, Mar 22 | D10: 24520981 | E10: 25901645 | F10: 24987811 | G10: 26006907 | H10: 25901645 | I10: =(D10+E10+F10+G10)/4 -> 25354336 | J10: =((H10-I10)/I10)*100 -> 2.1586407
B11: 5. Idul Fitri I | C11: Sunday, May 24 | D11: 22151895 | E11: 22742761 | F11: 23242825 | G11: 22572630 | H11: 22949802 | I11: =(D11+E11+F11+G11)/4 -> 22677528 | J11: =((H11-I11)/I11)*100 -> 1.2006336
B12: 6. Idul Fitri II | C12: Monday, May 25 | D12: 22742761 | E12: 23242825 | F12: 22572630 | G12: 22949802 | H12: 23457313 | I12: =(D12+E12+F12+G12)/4 -> 22877005 | J12: =((H12-I12)/I12)*100 -> 2.5366439
A13: Christian Holidays | B13: 1. Good Friday | C13: Friday, Apr 10 | D13: 22224364 | E13: 24161370 | F13: 23302242 | G13: 23273985 | H13: 23007013 | I13: =(D13+E13+F13+G13)/4 -> 23240490 | J13: =((H13-I13)/I13)*100 -> -1.0046133
B14: 2. Ascension Day | C14: Thursday, May 21 | D14: 23000644 | E14: 27058926 | F14: 23398859 | G14: 22151895 | H14: 22742761 | I14: =(D14+E14+F14+G14)/4 -> 23902581 | J14: =((H14-I14)/I14)*100 -> -4.8522791
B15: 3. Christmas | C15: Friday, Dec 25 | D15: 25465122 | E15: 26931676 | F15: 24803189 | G15: 25181154 | H15: 25456620 | I15: =(D15+E15+F15+G15)/4 -> 25595285 | J15: =((H15-I15)/I15)*100 -> -0.54176009
A16: Hindu, Buddhist, | B16: 1. Silent Day (Nyepi) | C16: Wednesday, Mar 25 | D16: 26006907 | E16: 25901645 | F16: 25002606 | G16: 24801785 | H16: 24601645 | I16: =(D16+E16+F16+G16)/4 -> 25428236 | J16: =((H16-I16)/I16)*100 -> -3.2506805
A17: and Chinese Holidays | B17: 2. Chinese New Year (Imlek) | C17: Saturday, Jan 25 | D17: 28134040 | E17: 29372832 | F17: 29493308 | G17: 27138620 | H17: 23110877 | I17: =(D17+E17+F17+G17)/4 -> 28534700 | J17: =((H17-I17)/I17)*100 -> -19.007814
B18: 3. Waisak | C18: Thursday, May 07 | D18: 23398859 | E18: 21973606 | F18: 22838017 | G18: 22732675 | H18: 22035484 | I18: =(D18+E18+F18+G18)/4 -> 22735789 | J18: =((H18-I18)/I18)*100 -> -3.0801889

Sheet 2021a
A1: RSUD ULIN Electrical Load Consumption During Special Holidays (Year 2021)
A3: Category | B3: Special Holiday | C3: Day / Date | D3: Day | I3: WDMAX | J3: LDMAX | K3: TLDMAX | L3: VLDMAX
D4: H-4 (Wh) | E4: H-3 (Wh) | F4: H-2 (Wh) | G4: H-1 (Wh) | H4: H (Wh)
A5: General Holidays | B5: 1. New Year | C5: Friday, Jan 01 | D5: 26362121 | E5: 24633072 | F5: 25633792 | G5: 23463371 | H5: 23718258 | I5: =(D5+E5+F5+G5)/4 -> 25023089 | J5: =((H5-I5)/I5)*100 -> -5.2145079 | K5: ='2020a'!J5 -> -4.8406691 | L5: =J5-K5 -> -0.37383879
B6: 2. Independence Day | C6: Tuesday, Aug 17 | D6: 24464888 | E6: 25477371 | F6: 23241235 | G6: 25411914 | H6: 23452361 | I6: =(D6+E6+F6+G6)/4 -> 24648852 | J6: =((H6-I6)/I6)*100 -> -4.8541444 | K6: ='2020a'!J6 -> -0.98948546 | L6: =J6-K6 -> -3.8646589
A7: Islamic Holidays | B7: 1. Idul Adha | C7: Tuesday, Jul 20 | D7: 23442566 | E7: 23481886 | F7: 21702795 | G7: 25998747 | H7: 22686862 | I7: =(D7+E7+F7+G7)/4 -> 23656498 | J7: =((H7-I7)/I7)*100 -> -4.0988182 | K7: ='2020a'!J7 -> -1.6997987 | L7: =J7-K7 -> -2.3990196
B8: 2. Islamic New Year | C8: Tuesday, Aug 10 | D8: 25064032 | E8: 25622147 | F8: 23650703 | G8: 23507110 | H8: 24934535 | I8: =(D8+E8+F8+G8)/4 -> 24460998 | J8: =((H8-I8)/I8)*100 -> 1.935886 | K8: ='2020a'!J8 -> 2.3842395 | L8: =J8-K8 -> -0.44835353
B9: 3. Maulid | C9: Tuesday, Oct 19 | D9: 28519671 | E9: 29260420 | F9: 30285710 | G9: 27039562 | H9: 27274020 | I9: =(D9+E9+F9+G9)/4 -> 28776341 | J9: =((H9-I9)/I9)*100 -> -5.2206802 | K9: ='2020a'!J9 -> 2.9757394 | L9: =J9-K9 -> -8.1964196
B10: 4. Isra Mi'raj | C10: Thursday, Mar 11 | D10: 23979209 | E10: 24342530 | F10: 26026584 | G10: 26684617 | H10: 24409354 | I10: =(D10+E10+F10+G10)/4 -> 25258235 | J10: =((H10-I10)/I10)*100 -> -3.3608099 | K10: ='2020a'!J10 -> 2.1586407 | L10: =J10-K10 -> -5.5194506
B11: 5. Idul Fitri I | C11: Thursday, May 13 | D11: 24755826 | E11: 24872874 | F11: 25198627 | G11: 24279438 | H11: 23852583 | I11: =(D11+E11+F11+G11)/4 -> 24776692 | J11: =((H11-I11)/I11)*100 -> -3.7297504 | K11: ='2020a'!J11 -> 1.2006336 | L11: =J11-K11 -> -4.9303841
B12: 6. Idul Fitri II | C12: Friday, May 14 | D12: 24872874 | E12: 25198627 | F12: 24279438 | G12: 23852583 | H12: 23441136 | I12: =(D12+E12+F12+G12)/4 -> 24550881 | J12: =((H12-I12)/I12)*100 -> -4.520183 | K12: ='2020a'!J12 -> 2.5366439 | L12: =J12-K12 -> -7.056827
A13: Christian Holidays | B13: 1. Good Friday | C13: Friday, Apr 02 | D13: 25719603 | E13: 25409161 | F13: 25820457 | G13: 25128781 | H13: 22751771 | I13: =(D13+E13+F13+G13)/4 -> 25519500 | J13: =((H13-I13)/I13)*100 -> -10.845545 | K13: ='2020a'!J13 -> -1.0046133 | L13: =J13-K13 -> -9.8409322
B14: 2. Ascension Day | C14: Thursday, May 13 | D14: 24755826 | E14: 24872874 | F14: 25198627 | G14: 24279438 | H14: 23852583 | I14: =(D14+E14+F14+G14)/4 -> 24776692 | J14: =((H14-I14)/I14)*100 -> -3.7297504 | K14: ='2020a'!J14 -> -4.8522791 | L14: =J14-K14 -> 1.1225287
B15: 3. Christmas | C15: Monday, Dec 25 | D15: 26516165 | E15: 27408592 | F15: 25976683 | G15: 26636426 | H15: 22815692 | I15: =(D15+E15+F15+G15)/4 -> 26634467 | J15: =((H15-I15)/I15)*100 -> -14.337718 | K15: ='2020a'!J15 -> -0.54176009 | L15: =J15-K15 -> -13.795958
A16: Hindu, Buddhist, | B16: 1. Silent Day (Nyepi) | C16: Sunday, Mar 14 | D16: 24409354 | E16: 25152062 | F16: 25952051 | G16: 27224238 | H16: 23287769 | I16: =(D16+E16+F16+G16)/4 -> 25684426 | J16: =((H16-I16)/I16)*100 -> -9.3311673 | K16: ='2020a'!J16 -> -3.2506805 | L16: =J16-K16 -> -6.0804868
A17: and Chinese Holidays | B17: 2. Chinese New Year (Imlek) | C17: Friday, Feb 12 | D17: 24822865 | E17: 24612050 | F17: 25128609 | G17: 25605729 | H17: 22254696 | I17: =(D17+E17+F17+G17)/4 -> 25042313 | J17: =((H17-I17)/I17)*100 -> -11.131629 | K17: ='2020a'!J17 -> -19.007814 | L17: =J17-K17 -> 7.8761851
B18: 3. Waisak | C18: Wednesday, May 26 | D18: 19097263 | E18: 22373731 | F18: 25978307 | G18: 25999101 | H18: 23862346 | I18: =(D18+E18+F18+G18)/4 -> 23362101 | J18: =((H18-I18)/I18)*100 -> 2.141267 | K18: ='2020a'!J18 -> -3.0801889 | L18: =J18-K18 -> 5.2214559

Sheet 2022a
A1: RSUD ULIN Electrical Load Consumption During Special Holidays (Year 2022)
A3: Category | B3: Special Holiday | C3: Day / Date | D3: Day | I3: WDMAX | J3: LDMAX | K3: TLDMAX | L3: VLDMAX
D4: H-4 (Wh) | E4: H-3 (Wh) | F4: H-2 (Wh) | G4: H-1 (Wh) | H4: H (Wh)
A5: General Holidays | B5: 1. New Year | C5: Saturday, Jan 01 | D5: 28045067 | E5: 27126320 | F5: 27503446 | G5: 26231291 | H5: 25726989 | I5: =(D5+E5+F5+G5)/4 -> 27226531 | J5: =((H5-I5)/I5)*100 -> -5.5076516 | K5: =('2020a'!J5+'2021a'!J5)/2 -> -5.0275885 | L5: =J5-K5 -> -0.48006314
B6: 2. Independence Day | C6: Wednesday, Aug 17 | D6: 26099256 | E6: 23081675 | F6: 27802201 | G6: 26751323 | H6: 23595416 | I6: =(D6+E6+F6+G6)/4 -> 25933614 | J6: =((H6-I6)/I6)*100 -> -9.0160879 | K6: =('2020a'!J6+'2021a'!J6)/2 -> -2.9218149 | L6: =J6-K6 -> -6.094273
A7: Islamic Holidays | B7: 1. Idul Adha | C7: Friday, Jul 09 | D7: 27305491 | E7: 26657436 | F7: 26772536 | G7: 25895474 | H7: 23221913 | I7: =(D7+E7+F7+G7)/4 -> 26657734 | J7: =((H7-I7)/I7)*100 -> -12.888645 | K7: =('2020a'!J7+'2021a'!J7)/2 -> -2.8993084 | L7: =J7-K7 -> -9.9893364
B8: 2. Islamic New Year | C8: Saturday, Jul 30 | D8: 27279482 | E8: 27192133 | F8: 25449599 | G8: 25989618 | H8: 23994466 | I8: =(D8+E8+F8+G8)/4 -> 26477708 | J8: =((H8-I8)/I8)*100 -> -9.3786157 | K8: =('2020a'!J8+'2021a'!J8)/2 -> 2.1600628 | L8: =J8-K8 -> -11.538678
B9: 3. Maulid | C9: Saturday, Oct 08 | D9: 27869896 | E9: 28150674 | F9: 27342435 | G9: 26449761 | H9: 24348237 | I9: =(D9+E9+F9+G9)/4 -> 27453191 | J9: =((H9-I9)/I9)*100 -> -11.309993 | K9: =('2020a'!J9+'2021a'!J9)/2 -> -1.1224704 | L9: =J9-K9 -> -10.187522
B10: 4. Isra Mi'raj | C10: Monday, Feb 28 | D10: 27198992 | E10: 25907785 | F10: 23350518 | G10: 22160100 | H10: 23370764 | I10: =(D10+E10+F10+G10)/4 -> 24654349 | J10: =((H10-I10)/I10)*100 -> -5.2063215 | K10: =('2020a'!J10+'2021a'!J10)/2 -> -0.60108463 | L10: =J10-K10 -> -4.6052368
B11: 5. Idul Fitri I | C11: Monday, May 02 | D11: 25328500 | E11: 27064561 | F11: 23719376 | G11: 22816454 | H11: 21973445 | I11: =(D11+E11+F11+G11)/4 -> 24732223 | J11: =((H11-I11)/I11)*100 -> -11.15459 | K11: =('2020a'!J11+'2021a'!J11)/2 -> -1.2645584 | L11: =J11-K11 -> -9.8900317
B12: 6. Idul Fitri II | C12: Tuesday, May 03 | D12: 27064561 | E12: 23719376 | F12: 22816454 | G12: 21973445 | H12: 22778254 | I12: =(D12+E12+F12+G12)/4 -> 23893459 | J12: =((H12-I12)/I12)*100 -> -4.667409 | K12: =('2020a'!J12+'2021a'!J12)/2 -> -0.99176956 | L12: =J12-K12 -> -3.6756394
A13: Christian Holidays | B13: 1. Good Friday | C13: Friday, Apr 15 | D13: 27745162 | E13: 27788987 | F13: 28655136 | G13: 28339705 | H13: 24624619 | I13: =(D13+E13+F13+G13)/4 -> 28132247 | J13: =((H13-I13)/I13)*100 -> -12.468353 | K13: =('2020a'!J13+'2021a'!J13)/2 -> -5.9250794 | L13: =J13-K13 -> -6.5432734
B14: 2. Ascension Day | C14: Thursday, May 26 | D14: 23930341 | E14: 28243786 | F14: 28868950 | G14: 29910077 | H14: 24654370 | I14: =(D14+E14+F14+G14)/4 -> 27738289 | J14: =((H14-I14)/I14)*100 -> -11.117912 | K14: =('2020a'!J14+'2021a'!J14)/2 -> -4.2910148 | L14: =J14-K14 -> -6.8268972
B15: 3. Christmas | C15: Sunday, Dec 25 | D15: 31059369 | E15: 30082948 | F15: 26653780 | G15: 25353530 | H15: 25043530 | I15: =(D15+E15+F15+G15)/4 -> 28287407 | J15: =((H15-I15)/I15)*100 -> -11.467566 | K15: =('2020a'!J15+'2021a'!J15)/2 -> -7.4397389 | L15: =J15-K15 -> -4.0278267
A16: Hindu, Buddhist, | B16: 1. Silent Day (Nyepi) | C16: Thursday, Mar 03 | D16: 22160100 | E16: 23370764 | F16: 27994017 | G16: 28188987 | H16: 27298992 | I16: =(D16+E16+F16+G16)/4 -> 25428467 | J16: =((H16-I16)/I16)*100 -> 7.3560291 | K16: =('2020a'!J16+'2021a'!J16)/2 -> -6.2909239 | L16: =J16-K16 -> 13.646953
A17: and Chinese Holidays | B17: 2. Chinese New Year (Imlek) | C17: Tuesday, Feb 01 | D17: 27935763 | E17: 26960717 | F17: 24599417 | G17: 29899691 | H17: 25825941 | I17: =(D17+E17+F17+G17)/4 -> 27348897 | J17: =((H17-I17)/I17)*100 -> -5.5686205 | K17: =('2020a'!J17+'2021a'!J17)/2 -> -15.069722 | L17: =J17-K17 -> 9.5011013
B18: 3. Waisak | C18: Monday, May 16 | D18: 27872745 | E18: 26727184 | F18: 26021100 | G18: 21420104 | H18: 23610308 | I18: =(D18+E18+F18+G18)/4 -> 25510283 | J18: =((H18-I18)/I18)*100 -> -7.4478801 | K18: =('2020a'!J18+'2021a'!J18)/2 -> -0.46946095 | L18: =J18-K18 -> -6.9784191

Sheet 2023a
A1: RSUD ULIN Electrical Load Consumption During Special Holidays (Year 2023)
A3: Forecasting using Fuzzy Type 1 Inference system
A4: Category | B4: Special Holiday | C4: Day / Date | D4: Day | I4: WDMAX | J4: LDMAX | K4: TLDMAX | L4: VLDMAX | M4: Output | N4: Forecast | O4: Peramalan | P4: Aktual | Q4: Error | V4: Error
D5: H-4 (Wh) | E5: H-3 (Wh) | F5: H-2 (Wh) | G5: H-1 (Wh) | H5: H (Wh) | M5: Forecast | N5: LDMAX | O5: P'MAX(Watthours) | P5: (Watthours) | Q5: (%)
A6: General Holidays | B6: 1. New Year | C6: Sunday, Jan 01 | D6: 24649306 | E6: 26388464 | F6: 25474318 | G6: 25889711 | H6: 21383235 | I6: =(D6+E6+F6+G6)/4 -> 25600450 | J6: =((H6-I6)/I6)*100 -> -16.473204 | K6: =('2020a'!J5+'2021a'!J5+'2022a'!J5)/3 -> -5.1876095 | L6: =J6-K6 -> -11.285594 | M6: -12 | N6: =M6+K6 -> -17.18761 | O6: =I6+((N6*I6)/100) -> 21200344 | P6: =H6 -> 21383235 | Q6: =-((O6-H6)/H6)*100 -> 0.85530116 | V6: =(O6-P6) -> -182891.06
B7: 2. Independence Day | C7: Thursday, Aug 17 | D7: 20767780 | E7: 29123880 | F7: 29726541 | G7: 29297504 | H7: 23369011 | I7: =(D7+E7+F7+G7)/4 -> 27228926 | J7: =((H7-I7)/I7)*100 -> -14.175787 | K7: =('2020a'!J6+'2021a'!J6+'2022a'!J6)/3 -> -4.9532393 | L7: =J7-K7 -> -9.2225478 | M7: -4.7677 | N7: =M7+K7 -> -9.7209393 | O7: =I7+((N7*I7)/100) -> 24582019 | P7: =H7 -> 23369011 | Q7: =((O7-H7)/H7)*100 -> 5.1906655 | V7: =(O7-P7) -> 1213007.2
A8: Islamic Holidays | B8: 1. Idul Adha | C8: Thursday, Jun 29 | D8: 22208043 | E8: 28933957 | F8: 29751614 | G8: 22312681 | H8: 20658325 | I8: =(D8+E8+F8+G8)/4 -> 25801574 | J8: =((H8-I8)/I8)*100 -> -19.933858 | K8: =('2020a'!J7+'2021a'!J7+'2022a'!J7)/3 -> -6.2290872 | L8: =J8-K8 -> -13.704771 | M8: 0 | N8: =M8+K8 -> -6.2290872 | O8: =I8+((N8*I8)/100) -> 24194371 | P8: =H8 -> 20658325 | Q8: =((O8-H8)/H8)*100 -> 17.116812 | V8: =(O8-P8) -> 3536046.7
B9: 2. Islamic New Year | C9: Wednesday, Jul 19 | D9: 27025283 | E9: 21083588 | F9: 28915431 | G9: 29089796 | H9: 23414288 | I9: =(D9+E9+F9+G9)/4 -> 26528525 | J9: =((H9-I9)/I9)*100 -> -11.739199 | K9: =('2020a'!J8+'2021a'!J8+'2022a'!J8)/3 -> -1.6861634 | L9: =J9-K9 -> -10.053036 | M9: -9 | N9: =M9+K9 -> -10.686163 | O9: =I9+((N9*I9)/100) -> 23693643 | P9: =H9 -> 23414288 | Q9: =((O9-H9)/H9)*100 -> 1.1930957 | V9: =(O9-P9) -> 279354.86
B10: 3. Maulid | C10: Thursday, Sep 28 | D10: 23272362 | E10: 30686318 | F10: 29710821 | G10: 29906454 | H10: 23798221 | I10: =(D10+E10+F10+G10)/4 -> 28393989 | J10: =((H10-I10)/I10)*100 -> -16.185708 | K10: =('2020a'!J9+'2021a'!J9+'2022a'!J9)/3 -> -4.5183112 | L10: =J10-K10 -> -11.667397 | M10: -9 | N10: =M10+K10 -> -13.518311 | O10: =I10+((N10*I10)/100) -> 24555601 | P10: =H10 -> 23798221 | Q10: =((O10-H10)/H10)*100 -> 3.1825084 | V10: =(O10-P10) -> 757380.38
B11: 4. Isra Mi'raj | C11: Saturday, Feb 18 | D11: 27210185 | E11: 27031165 | F11: 27719443 | G11: 27294019 | H11: 25703680 | I11: =(D11+E11+F11+G11)/4 -> 27313703 | J11: =((H11-I11)/I11)*100 -> -5.894563 | K11: =('2020a'!J10+'2021a'!J10+'2022a'!J10)/3 -> -2.1361636 | L11: =J11-K11 -> -3.7583995 | M11: -4.5 | N11: =M11+K11 -> -6.6361636 | O11: =I11+((N11*I11)/100) -> 25501121 | P11: =H11 -> 25703680 | Q11: =((O11-H11)/H11)*100*-1 -> 0.78805281 | V11: =(O11-P11) -> -202558.57
B12: 5. Idul Fitri I | C12: Saturday, Apr 22 | D12: 28152491 | E12: 24068160 | F12: 21402954 | G12: 19347441 | H12: 18556040 | I12: =(D12+E12+F12+G12)/4 -> 23242761 | J12: =((H12-I12)/I12)*100 -> -20.164222 | K12: =('2020a'!J11+'2021a'!J11+'2022a'!J11)/3 -> -4.5612356 | L12: =J12-K12 -> -15.602986 | M12: -6 | N12: =M12+K12 -> -10.561236 | O12: =I12+((N12*I12)/100) -> 20788039 | P12: =H12 -> 18556040 | Q12: =((O12-H12)/H12)*100 -> 12.028424 | V12: =(O12-P12) -> 2231999.1
B13: 6. Idul Fitri II | C13: Sunday, Apr 23 | D13: 24068160 | E13: 21402954 | F13: 19347441 | G13: 18556040 | H13: 20061148 | I13: =(D13+E13+F13+G13)/4 -> 20843649 | J13: =((H13-I13)/I13)*100 -> -3.7541463 | K13: =('2020a'!J12+'2021a'!J12+'2022a'!J12)/3 -> -2.2169827 | L13: =J13-K13 -> -1.5371636 | M13: 0 | N13: =M13+K13 -> -2.2169827 | O13: =I13+((N13*I13)/100) -> 20381549 | P13: =H13 -> 20061148 | Q13: =((O13-H13)/H13)*100 -> 1.5971219 | V13: =(O13-P13) -> 320400.99
A14: Christian Holidays | B14: 1. Good Friday | C14: Friday, Apr 07 | D14: 26929203 | E14: 26205002 | F14: 27649232 | G14: 28487018 | H14: 22518593 | I14: =(D14+E14+F14+G14)/4 -> 27317614 | J14: =((H14-I14)/I14)*100 -> -17.567498 | K14: =('2020a'!J13+'2021a'!J13+'2022a'!J13)/3 -> -8.1061705 | L14: =J14-K14 -> -9.4613273 | M14: -4.5 | N14: =M14+K14 -> -12.606171 | O14: =I14+((N14*I14)/100) -> 23873909 | P14: =H14 -> 22518593 | Q14: =((O14-H14)/H14)*100 -> 6.0186542 | V14: =(O14-P14) -> 1355316.2
B15: 2. Ascension Day | C15: Thursday, May 18 | D15: 23185443 | E15: 30488212 | F15: 31284871 | G15: 30880026 | H15: 25094944 | I15: =(D15+E15+F15+G15)/4 -> 28959638 | J15: =((H15-I15)/I15)*100 -> -13.345104 | K15: =('2020a'!J14+'2021a'!J14+'2022a'!J14)/3 -> -6.5666472 | L15: =J15-K15 -> -6.7784571 | M15: -5.00054 | N15: =M15+K15 -> -11.567187 | O15: =I15+((N15*I15)/100) -> 25609822 | P15: =H15 -> 25094944 | Q15: =((O15-H15)/H15)*100 -> 2.0517215 | V15: =(O15-P15) -> 514878.36
B16: 3. Christmas | C16: Monday, Dec 25 | D16: 33735338 | E16: 32642075 | F16: 31107022 | G16: 22935018 | H16: 23465167 | I16: =(D16+E16+F16+G16)/4 -> 30104863 | J16: =((H16-I16)/I16)*100 -> -22.055229 | K16: =('2020a'!J15+'2021a'!J15+'2022a'!J15)/3 -> -8.7823478 | L16: =J16-K16 -> -13.272881 | M16: -4.5 | N16: =M16+K16 -> -13.282348 | O16: =I16+((N16*I16)/100) -> 26106231 | P16: =H16 -> 23465167 | Q16: =((O16-H16)/H16)*100 -> 11.255253 | V16: =(O16-P16) -> 2641063.9
A17: Hindu, Buddhist, | B17: 1. Silent Day (Nyepi) | C17: Wednesday, Mar 22 | D17: 26571839 | E17: 21378547 | F17: 28930032 | G17: 29008866 | H17: 23458006 | I17: =(D17+E17+F17+G17)/4 -> 26472321 | J17: =((H17-I17)/I17)*100 -> -11.386668 | K17: =('2020a'!J16+'2021a'!J16+'2022a'!J16)/3 -> -1.7419396 | L17: =J17-K17 -> -9.6447284 | M17: 0 | N17: =M17+K17 -> -1.7419396 | O17: =I17+((N17*I17)/100) -> 26011189 | P17: =H17 -> 23458006 | Q17: =((O17-H17)/H17)*100 -> 10.88406 | V17: =(O17-P17) -> 2553183.5
A18: and Chinese Holidays | B18: 2. Chinese New Year (Imlek) | C18: Sunday, Jan 22 | D18: 27701896 | E18: 27860853 | F18: 25524164 | G18: 26210529 | H18: 20598511 | I18: =(D18+E18+F18+G18)/4 -> 26824361 | J18: =((H18-I18)/I18)*100 -> -23.209684 | K18: =('2020a'!J17+'2021a'!J17+'2022a'!J17)/3 -> -11.902688 | L18: =J18-K18 -> -11.306996 | M18: 0 | N18: =M18+K18 -> -11.902688 | O18: =I18+((N18*I18)/100) -> 23631541 | P18: =H18 -> 20598511 | Q18: =((O18-H18)/H18)*100 -> 14.724508 | V18: =(O18-P18) -> 3033029.4
B19: 3.Waisak | C19: Sunday, Jun 04 | D19: 32850749 | E19: 26168015 | F19: 25505982 | G19: 30188565 | H19: 23319886 | I19: =(D19+E19+F19+G19)/4 -> 28678328 | J19: =((H19-I19)/I19)*100 -> -18.68464 | K19: =('2020a'!J18+'2021a'!J18+'2022a'!J18)/3 -> -2.7956007 | L19: =J19-K19 -> -15.889039 | M19: -6.41 | N19: =M19+K19 -> -9.2056007 | O19: =I19+((N19*I19)/100) -> 26038316 | P19: =H19 -> 23319886 | Q19: =((O19-H19)/H19)*100 -> 11.657133 | V19: =(O19-P19) -> 2718430
P20: MAPE | Q20: =SUM(Q6:Q19)/14 -> 7.038808 | R20: RMSE | S20: =SQRT(SUMXMY2(O6:O19, P6:P19) / COUNT(P6:P19)) -> 1926705.3 | T20: R2 | U20: =RSQ(O6:O19,P6:P19) -> 0.629261 | V20: MAE | W20: {=AVERAGE(ABS(V6:V19))} -> 1538538.6 | X20: {=SUMPRODUCT(ABS(O6:O19 - P6:P19)) / COUNT(O6:O19)} -> 1538538.6
A22: Forecasting using Interval Type 2 Fuzzy Inference system
A23: Category | B23: Special Holiday | C23: Day / Date | D23: Day | I23: WDMAX | J23: LDMAX | K23: TLDMAX | L23: VLDMAX | M23: Output | N23: Forecast | O23: Peramalan | P23: Aktual | Q23: Error
D24: H-4 (Wh) | E24: H-3 (Wh) | F24: H-2 (Wh) | G24: H-1 (Wh) | H24: H (Wh) | M24: Forecast | N24: LDMAX | O24: P'MAX(Watthours) | P24: (Watthours) | Q24: (%)
A25: General Holidays | B25: 1. New Year | C25: Sunday, Jan 01 | D25: 24649306 | E25: 26388464 | F25: 25474318 | G25: 25889711 | H25: 21383235 | I25: 25600450 | J25: -16.473204 | K25: -5.1876095 | L25: -11.285594 | M25: -12 | N25: =M25+K25 -> -17.18761 | O25: =I25+((N25*I25)/100) -> 21200344 | P25: =H25 -> 21383235 | Q25: =-((O25-H25)/H25)*100 -> 0.85530116 | V25: =(O25-P25) -> -182891.06
B26: 2. Independence Day | C26: Thursday, Aug 17 | D26: 20767780 | E26: 29123880 | F26: 29726541 | G26: 29297504 | H26: 23369011 | I26: 27228926 | J26: -14.175787 | K26: -4.9532393 | L26: -9.2225478 | M26: -6 | N26: =M26+K26 -> -10.953239 | O26: =I26+((N26*I26)/100) -> 24246477 | P26: =H26 -> 23369011 | Q26: =((O26-H26)/H26)*100 -> 3.7548236 | V26: =(O26-P26) -> 877465.17
A27: Islamic Holidays | B27: 1. Idul Adha | C27: Thursday, Jun 29 | D27: 22208043 | E27: 28933957 | F27: 29751614 | G27: 22312681 | H27: 20658325 | I27: 25801574 | J27: -19.933858 | K27: -6.2290872 | L27: -13.704771 | M27: 0 | N27: =M27+K27 -> -6.2290872 | O27: =I27+((N27*I27)/100) -> 24194371 | P27: =H27 -> 20658325 | Q27: =((O27-H27)/H27)*100 -> 17.116812 | V27: =(O27-P27) -> 3536046.7
B28: 2. Islamic New Year | C28: Wednesday, Jul 19 | D28: 27025283 | E28: 21083588 | F28: 28915431 | G28: 29089796 | H28: 23414288 | I28: 26528525 | J28: -11.739199 | K28: -1.6861634 | L28: -10.053036 | M28: -9 | N28: =M28+K28 -> -10.686163 | O28: =I28+((N28*I28)/100) -> 23693643 | P28: =H28 -> 23414288 | Q28: =((O28-H28)/H28)*100 -> 1.1930957 | V28: =(O28-P28) -> 279354.86
B29: 3. Maulid | C29: Thursday, Sep 28 | D29: 23272362 | E29: 30686318 | F29: 29710821 | G29: 29906454 | H29: 23798221 | I29: 28393989 | J29: -16.185708 | K29: -4.5183112 | L29: -11.667397 | M29: -9 | N29: =M29+K29 -> -13.518311 | O29: =I29+((N29*I29)/100) -> 24555601 | P29: =H29 -> 23798221 | Q29: =((O29-H29)/H29)*100 -> 3.1825084 | V29: =(O29-P29) -> 757380.38
B30: 4. Isra Mi'raj | C30: Saturday, Feb 18 | D30: 27210185 | E30: 27031165 | F30: 27719443 | G30: 27294019 | H30: 25703680 | I30: 27313703 | J30: -5.894563 | K30: -2.1361636 | L30: -3.7583995 | M30: -4.5 | N30: =M30+K30 -> -6.6361636 | O30: =I30+((N30*I30)/100) -> 25501121 | P30: =H30 -> 25703680 | Q30: =-((O30-H30)/H30)*100 -> 0.78805281 | V30: =(O30-P30) -> -202558.57
B31: 5. Idul Fitri I | C31: Saturday, Apr 22 | D31: 28152491 | E31: 24068160 | F31: 21402954 | G31: 19347441 | H31: 18556040 | I31: 23242761 | J31: -20.164222 | K31: -4.5612356 | L31: -15.602986 | M31: -6 | N31: =M31+K31 -> -10.561236 | O31: =I31+((N31*I31)/100) -> 20788039 | P31: =H31 -> 18556040 | Q31: =((O31-H31)/H31)*100 -> 12.028424 | V31: =(O31-P31) -> 2231999.1
B32: 6. Idul Fitri II | C32: Sunday, Apr 23 | D32: 24068160 | E32: 21402954 | F32: 19347441 | G32: 18556040 | H32: 20061148 | I32: 20843649 | J32: -3.7541463 | K32: -2.2169827 | L32: -1.5371636 | M32: 0 | N32: =M32+K32 -> -2.2169827 | O32: =I32+((N32*I32)/100) -> 20381549 | P32: =H32 -> 20061148 | Q32: =((O32-H32)/H32)*100 -> 1.5971219 | V32: =(O32-P32) -> 320400.99
A33: Christian Holidays | B33: 1. Good Friday | C33: Friday, Apr 07 | D33: 26929203 | E33: 26205002 | F33: 27649232 | G33: 28487018 | H33: 22518593 | I33: 27317614 | J33: -17.567498 | K33: -8.1061705 | L33: -9.4613273 | M33: -4.5 | N33: =M33+K33 -> -12.606171 | O33: =I33+((N33*I33)/100) -> 23873909 | P33: =H33 -> 22518593 | Q33: =((O33-H33)/H33)*100 -> 6.0186542 | V33: =(O33-P33) -> 1355316.2
B34: 2. Ascension Day | C34: Thursday, May 18 | D34: 23185443 | E34: 30488212 | F34: 31284871 | G34: 30880026 | H34: 25094944 | I34: 28959638 | J34: -13.345104 | K34: -6.5666472 | L34: -6.7784571 | M34: -4.8236 | N34: =M34+K34 -> -11.390247 | O34: =I34+((N34*I34)/100) -> 25661064 | P34: =H34 -> 25094944 | Q34: =((O34-H34)/H34)*100 -> 2.2559108 | V34: =(O34-P34) -> 566119.54
B35: 3. Christmas | C35: Monday, Dec 25 | D35: 33735338 | E35: 32642075 | F35: 31107022 | G35: 22935018 | H35: 23465167 | I35: 30104863 | J35: -22.055229 | K35: -8.7823478 | L35: -13.272881 | M35: -4.5 | N35: =M35+K35 -> -13.282348 | O35: =I35+((N35*I35)/100) -> 26106231 | P35: =H35 -> 23465167 | Q35: =((O35-H35)/H35)*100 -> 11.255253 | V35: =(O35-P35) -> 2641063.9
A36: Hindu, Buddhist, | B36: 1. Silent Day (Nyepi) | C36: Wednesday, Mar 22 | D36: 26571839 | E36: 21378547 | F36: 28930032 | G36: 29008866 | H36: 23458006 | I36: 26472321 | J36: -11.386668 | K36: -1.7419396 | L36: -9.6447284 | M36: 0 | N36: =M36+K36 -> -1.7419396 | O36: =I36+((N36*I36)/100) -> 26011189 | P36: =H36 -> 23458006 | Q36: =((O36-H36)/H36)*100 -> 10.88406 | V36: =(O36-P36) -> 2553183.5
A37: and Chinese Holidays | B37: 2. Chinese New Year (Imlek) | C37: Sunday, Jan 22 | D37: 27701896 | E37: 27860853 | F37: 25524164 | G37: 26210529 | H37: 20598511 | I37: 26824361 | J37: -23.209684 | K37: -11.902688 | L37: -11.306996 | M37: 0 | N37: =M37+K37 -> -11.902688 | O37: =I37+((N37*I37)/100) -> 23631541 | P37: =H37 -> 20598511 | Q37: =((O37-H37)/H37)*100 -> 14.724508 | V37: =(O37-P37) -> 3033029.4
B38: 3.Waisak | C38: Sunday, Jun 04 | D38: 32850749 | E38: 26168015 | F38: 25505982 | G38: 30188565 | H38: 23319886 | I38: 28678328 | J38: -18.68464 | K38: -2.7956007 | L38: -15.889039 | M38: -6 | N38: =M38+K38 -> -8.7956007 | O38: =I38+((N38*I38)/100) -> 26155897 | P38: =H38 -> 23319886 | Q38: =((O38-H38)/H38)*100 -> 12.161343 | V38: =(O38-P38) -> 2836011.2
P39: MAPE | Q39: =SUM(Q25:Q38)/14 -> 6.9868478 | R39: RMSE | S39: =SQRT(SUMXMY2(O25:O38, P25:P38) / COUNT(P25:P38)) -> 1926836 | T39: R2 | U39: =RSQ(O25:O38,P25:P38) -> 0.62265263 | V39: MAE | W39: {=AVERAGE(ABS(V25:V38))} -> 1526630 | X39: {=SUMPRODUCT(ABS(O25:O38 - P25:P38)) / COUNT(O25:O38)} -> 1526630
A41: Forecasting using IT2FIS-CSA
A42: Category | B42: Special Holiday | C42: Day / Date | D42: Day | I42: WDMAX | J42: LDMAX | K42: TLDMAX | L42: VLDMAX | M42: Output | N42: Forecast | O42: Peramalan | P42: Aktual | Q42: Error
D43: H-4 (Wh) | E43: H-3 (Wh) | F43: H-2 (Wh) | G43: H-1 (Wh) | H43: H (Wh) | M43: Forecast | N43: LDMAX | O43: P'MAX(Watthours) | P43: (Watthours) | Q43: (%)
...

Sheet Result VLD 2023
B1: RESULT FORCASTING VLD YEAR 2023
B3: Type-1 | E3: IT2-FIS | H3: IT2FIS-CSA | K3: IT2FIS-FA | N3: IT2FIS-ZOA | Q3: IT2FIS-OOA
B4: Actual | C4: Forecast | D4: Error | E4: Actual | F4: Forecast | G4: Error | H4: Actual | I4: Forecast | J4: Error | K4: Actual | L4: Forecast | M4: Error | N4: Actual | O4: Forecast | P4: Error | Q4: Actual | R4: Forecast | S4: Error
B5: ='2023a'!L6 -> -11.285594 | C5: ='2023a'!M6 -> -12 | D5: =ABS(B5-C5) -> 0.71440566 | E5: ='2023a'!L25 -> -11.285594 | F5: ='2023a'!M25 -> -12 | G5: =ABS(F5-E5) -> 0.71440566 | H5: ='2023a'!L44 -> -11.285594 | I5: ='2023a'!M44 -> -11.9334 | J5: =ABS(I5-H5) -> 0.64780566 | K5: ='2023a'!L63 -> -11.285594 | L5: ='2023a'!M63 -> -12.0103 | M5: =ABS(L5-K5) -> 0.72470566 | N5: ='2023a'!L82 -> -11.285594 | O5: ='2023a'!M82 -> -11.9009 | P5: =ABS(O5-N5) -> 0.61530566 | Q5: ='2023a'!L102 -> -11.285594 | R5: ='2023a'!M102 -> -11.8946 | S5: =ABS(R5-Q5) -> 0.60900566
B6: ='2023a'!L7 -> -9.2225478 | C6: ='2023a'!M7 -> -4.7677 | D6: =ABS(B6-C6) -> 4.4548478 | E6: ='2023a'!L26 -> -9.2225478 | F6: ='2023a'!M26 -> -6 | G6: =ABS(F6-E6) -> 3.2225478 | H6: ='2023a'!L45 -> -9.2225478 | I6: ='2023a'!M45 -> -6 | J6: =ABS(I6-H6) -> 3.2225478 | K6: ='2023a'!L64 -> -9.2225478 | L6: ='2023a'!M64 -> -6 | M6: =ABS(L6-K6) -> 3.2225478 | N6: ='2023a'!L83 -> -9.2225478 | O6: ='2023a'!M83 -> -6 | P6: =ABS(O6-N6) -> 3.2225478 | Q6: ='2023a'!L103 -> -9.2225478 | R6: ='2023a'!M103 -> -6 | S6: =ABS(R6-Q6) -> 3.2225478
B7: ='2023a'!L8 -> -13.704771 | C7: ='2023a'!M8 -> 0 | D7: =ABS(B7-C7) -> 13.704771 | E7: ='2023a'!L27 -> -13.704771 | F7: ='2023a'!M27 -> 0 | G7: =ABS(F7-E7) -> 13.704771 | H7: ='2023a'!L46 -> -13.704771 | I7: ='2023a'!M46 -> 0 | J7: =ABS(I7-H7) -> 13.704771 | K7: ='2023a'!L65 -> -13.704771 | L7: ='2023a'!M65 -> 0 | M7: =ABS(L7-K7) -> 13.704771 | N7: ='2023a'!L84 -> -13.704771 | O7: ='2023a'!M84 -> 0 | P7: =ABS(O7-N7) -> 13.704771 | Q7: ='2023a'!L104 -> -13.704771 | R7: ='2023a'!M104 -> 0 | S7: =ABS(R7-Q7) -> 13.704771
B8: ='2023a'!L9 -> -10.053036 | C8: ='2023a'!M9 -> -9 | D8: =ABS(B8-C8) -> 1.0530358 | E8: ='2023a'!L28 -> -10.053036 | F8: ='2023a'!M28 -> -9 | G8: =ABS(F8-E8) -> 1.0530358 | H8: ='2023a'!L47 -> -10.053036 | I8: ='2023a'!M47 -> -9 | J8: =ABS(I8-H8) -> 1.0530358 | K8: ='2023a'!L66 -> -10.053036 | L8: ='2023a'!M66 -> -9 | M8: =ABS(L8-K8) -> 1.0530358 | N8: ='2023a'!L85 -> -10.053036 | O8: ='2023a'!M85 -> -9 | P8: =ABS(O8-N8) -> 1.0530358 | Q8: ='2023a'!L105 -> -10.053036 | R8: ='2023a'!M105 -> -9 | S8: =ABS(R8-Q8) -> 1.0530358
B9: ='2023a'!L10 -> -11.667397 | C9: ='2023a'!M10 -> -9 | D9: =ABS(B9-C9) -> 2.6673969 | E9: ='2023a'!L29 -> -11.667397 | F9: ='2023a'!M29 -> -9 | G9: =ABS(F9-E9) -> 2.6673969 | H9: ='2023a'!L48 -> -11.667397 | I9: ='2023a'!M48 -> -9 | J9: =ABS(I9-H9) -> 2.6673969 | K9: ='2023a'!L67 -> -11.667397 | L9: ='2023a'!M67 -> -9 | M9: =ABS(L9-K9) -> 2.6673969 | N9: ='2023a'!L86 -> -11.667397 | O9: ='2023a'!M86 -> -9 | P9: =ABS(O9-N9) -> 2.6673969 | Q9: ='2023a'!L106 -> -11.667397 | R9: ='2023a'!M106 -> -9 | S9: =ABS(R9-Q9) -> 2.6673969
B10: ='2023a'!L11 -> -3.7583995 | C10: ='2023a'!M11 -> -4.5 | D10: =ABS(B10-C10) -> 0.74160054 | E10: ='2023a'!L30 -> -3.7583995 | F10: ='2023a'!M30 -> -4.5 | G10: =ABS(F10-E10) -> 0.74160054 | H10: ='2023a'!L49 -> -3.7583995 | I10: ='2023a'!M49 -> -4.5 | J10: =ABS(I10-H10) -> 0.74160054 | K10: ='2023a'!L68 -> -3.7583995 | L10: ='2023a'!M68 -> -4.5 | M10: =ABS(L10-K10) -> 0.74160054 | N10: ='2023a'!L87 -> -3.7583995 | O10: ='2023a'!M87 -> -4.5 | P10: =ABS(O10-N10) -> 0.74160054 | Q10: ='2023a'!L107 -> -3.7583995 | R10: ='2023a'!M107 -> -4.5 | S10: =ABS(R10-Q10) -> 0.74160054
B11: ='2023a'!L12 -> -15.602986 | C11: ='2023a'!M12 -> -6 | D11: =ABS(B11-C11) -> 9.6029859 | E11: ='2023a'!L31 -> -15.602986 | F11: ='2023a'!M31 -> -6 | G11: =ABS(F11-E11) -> 9.6029859 | H11: ='2023a'!L50 -> -15.602986 | I11: ='2023a'!M50 -> -6 | J11: =ABS(I11-H11) -> 9.6029859 | K11: ='2023a'!L69 -> -15.602986 | L11: ='2023a'!M69 -> -6 | M11: =ABS(L11-K11) -> 9.6029859 | N11: ='2023a'!L88 -> -15.602986 | O11: ='2023a'!M88 -> -6 | P11: =ABS(O11-N11) -> 9.6029859 | Q11: ='2023a'!L108 -> -15.602986 | R11: ='2023a'!M108 -> -6 | S11: =ABS(R11-Q11) -> 9.6029859
B12: ='2023a'!L13 -> -1.5371636 | C12: ='2023a'!M13 -> 0 | D12: =ABS(B12-C12) -> 1.5371636 | E12: ='2023a'!L32 -> -1.5371636 | F12: ='2023a'!M32 -> 0 | G12: =ABS(F12-E12) -> 1.5371636 | H12: ='2023a'!L51 -> -1.5371636 | I12: ='2023a'!M51 -> 0 | J12: =ABS(I12-H12) -> 1.5371636 | K12: ='2023a'!L70 -> -1.5371636 | L12: ='2023a'!M70 -> 0 | M12: =ABS(L12-K12) -> 1.5371636 | N12: ='2023a'!L89 -> -1.5371636 | O12: ='2023a'!M89 -> 0 | P12: =ABS(O12-N12) -> 1.5371636 | Q12: ='2023a'!L109 -> -1.5371636 | R12: ='2023a'!M109 -> 0 | S12: =ABS(R12-Q12) -> 1.5371636
B13: ='2023a'!L14 -> -9.4613273 | C13: ='2023a'!M14 -> -4.5 | D13: =ABS(B13-C13) -> 4.9613273 | E13: ='2023a'!L33 -> -9.4613273 | F13: ='2023a'!M33 -> -4.5 | G13: =ABS(F13-E13) -> 4.9613273 | H13: ='2023a'!L52 -> -9.4613273 | I13: ='2023a'!M52 -> -4.5 | J13: =ABS(I13-H13) -> 4.9613273 | K13: ='2023a'!L71 -> -9.4613273 | L13: ='2023a'!M71 -> -4.5 | M13: =ABS(L13-K13) -> 4.9613273 | N13: ='2023a'!L90 -> -9.4613273 | O13: ='2023a'!M90 -> -4.5 | P13: =ABS(O13-N13) -> 4.9613273 | Q13: ='2023a'!L110 -> -9.4613273 | R13: ='2023a'!M110 -> -4.5 | S13: =ABS(R13-Q13) -> 4.9613273
B14: ='2023a'!L15 -> -6.7784571 | C14: ='2023a'!M15 -> -5.00054 | D14: =ABS(B14-C14) -> 1.7779171 | E14: ='2023a'!L34 -> -6.7784571 | F14: ='2023a'!M34 -> -4.8236 | G14: =ABS(F14-E14) -> 1.9548571 | H14: ='2023a'!L53 -> -6.7784571 | I14: ='2023a'!M53 -> -4.7571 | J14: =ABS(I14-H14) -> 2.0213571 | K14: ='2023a'!L72 -> -6.7784571 | L14: ='2023a'!M72 -> -4.8234 | M14: =ABS(L14-K14) -> 1.9550571 | N14: ='2023a'!L91 -> -6.7784571 | O14: ='2023a'!M91 -> -4.764 | P14: =ABS(O14-N14) -> 2.0144571 | Q14: ='2023a'!L111 -> -6.7784571 | R14: ='2023a'!M111 -> -4.802 | S14: =ABS(R14-Q14) -> 1.9764571
B15: ='2023a'!L16 -> -13.272881 | C15: ='2023a'!M16 -> -4.5 | D15: =ABS(B15-C15) -> 8.7728813 | E15: ='2023a'!L35 -> -13.272881 | F15: ='2023a'!M35 -> -4.5 | G15: =ABS(F15-E15) -> 8.7728813 | H15: ='2023a'!L54 -> -13.272881 | I15: ='2023a'!M54 -> -4.5 | J15: =ABS(I15-H15) -> 8.7728813 | K15: ='2023a'!L73 -> -13.272881 | L15: ='2023a'!M73 -> -4.5 | M15: =ABS(L15-K15) -> 8.7728813 | N15: ='2023a'!L92 -> -13.272881 | O15: ='2023a'!M92 -> -4.5 | P15: =ABS(O15-N15) -> 8.7728813 | Q15: ='2023a'!L112 -> -13.272881 | R15: ='2023a'!M112 -> -4.5 | S15: =ABS(R15-Q15) -> 8.7728813
B16: ='2023a'!L17 -> -9.6447284 | C16: ='2023a'!M17 -> 0 | D16: =ABS(B16-C16) -> 9.6447284 | E16: ='2023a'!L36 -> -9.6447284 | F16: ='2023a'!M36 -> 0 | G16: =ABS(F16-E16) -> 9.6447284 | H16: ='2023a'!L55 -> -9.6447284 | I16: ='2023a'!M55 -> 0 | J16: =ABS(I16-H16) -> 9.6447284 | K16: ='2023a'!L74 -> -9.6447284 | L16: ='2023a'!M74 -> 0 | M16: =ABS(L16-K16) -> 9.6447284 | N16: ='2023a'!L93 -> -9.6447284 | O16: ='2023a'!M93 -> 0 | P16: =ABS(O16-N16) -> 9.6447284 | Q16: ='2023a'!L113 -> -9.6447284 | R16: ='2023a'!M113 -> 0 | S16: =ABS(R16-Q16) -> 9.6447284
... B18: ='2023a'!L19 -> -15.889039 | C18: ='2023a'!M19 -> -6.41 | D18: =ABS(B18-C18) -> 9.4790395 | E18: ='2023a'!L38 -> -15.889039 | F18: ='2023a'!M38 -> -6 | G18: =ABS(F18-E18) -> 9.8890395 | H18: ='2023a'!L57 -> -15.889039 | I18: ='2023a'!M57 -> -6 | J18: =ABS(I18-H18) -> 9.8890395 | K18: ='2023a'!L76 -> -15.889039 | L18: ='2023a'!M76 -> -6 | M18: =ABS(L18-K18) -> 9.8890395 | N18: ='2023a'!L95 -> -15.889039 | O18: ='2023a'!M95 -> -6 | P18: =ABS(O18-N18) -> 9.8890395 | Q18: ='2023a'!L115 -> -15.889039 | R18: ='2023a'!M115 -> -6.12 | S18: =ABS(R18-Q18) -> 9.7690395

Sheet 2024a
A1: RSUD ULIN Electrical Load Consumption During Special Holidays (Year 2024)
A3: Forecasting using Fuzzy Type 1 Inference system
A4: Category | B4: Special Holiday | C4: Day / Date | D4: Day | I4: WDMAX | J4: LDMAX | K4: TLDMAX | L4: VLDMAX | M4: Output | N4: Forecast | O4: Peramalan | P4: Aktual | Q4: Error | V4: Error
D5: H-4 (Wh) | E5: H-3 (Wh) | F5: H-2 (Wh) | G5: H-1 (Wh) | H5: H (Wh) | M5: Forecast | N5: LDMAX | O5: P'MAX(Watthours) | P5: (Watthours) | Q5: (%)
A6: General Holidays | B6: 1. New Year | C6: Monday, Jan 01 | D6: 31962075 | E6: 31389832 | F6: 30887111 | G6: 27674659 | H6: 25001165 | I6: =(D6+E6+F6+G6)/4 -> 30478419 | J6: =((H6-I6)/I6)*100 -> -17.970926 | K6: =('2020a'!J5+'2021a'!J5+'2022a'!J5+'2023a'!J6)/4 -> -8.0090081 | L6: =J6-K6 -> -9.9619177 | M6: -13.7527 | N6: =M6+K6 -> -21.761708 | O6: =I6+((N6*I6)/100) -> 23845795 | P6: =H6 -> 25001165 | Q6: =ABS((O6-H6)/H6)*100 -> 4.6212667 | V6: =(O6-P6) -> -1155370.5
B7: 2. Independence Day | C7: Saturday, Aug 17 | D7: 27235140 | E7: 28261723 | F7: 29261318 | G7: 25243722 | H7: 24512818 | I7: =(D7+E7+F7+G7)/4 -> 27500476 | J7: =((H7-I7)/I7)*100 -> -10.864023 | K7: =('2020a'!J6+'2021a'!J6+'2022a'!J6+'2023a'!J7)/4 -> -7.2588762 | L7: =J7-K7 -> -3.6051464 | M7: -8.627 | N7: =M7+K7 -> -15.885876 | O7: =I7+((N7*I7)/100) -> 23131784 | P7: =H7 -> 24512818 | Q7: =ABS((O7-H7)/H7)*100 -> 5.6339244 | V7: =(O7-P7) -> -1381033.6
A8: Islamic Holidays | B8: 1. Idul Adha | C8: Monday, Jun 17 | D8: 31957263 | E8: 31021032 | F8: 30016114 | G8: 25024126 | H8: 24126175 | I8: =(D8+E8+F8+G8)/4 -> 29504634 | J8: =((H8-I8)/I8)*100 -> -18.229199 | K8: =('2020a'!J7+'2021a'!J7+'2022a'!J7+'2023a'!J8)/4 -> -9.65528 | L8: =J8-K8 -> -8.5739194 | M8: 0 | N8: =M8+K8 -> -9.65528 | O8: =I8+((N8*I8)/100) -> 26655879 | P8: =H8 -> 24126175 | Q8: =ABS((O8-H8)/H8)*100 -> 10.485307 | V8: =(O8-P8) -> 2529703.5
B9: 2. Islamic New Year | C9: Sunday, Jul 07 | D9: 30050153 | E9: 26598716 | F9: 26845796 | G9: 27003129 | H9: 25429719 | I9: =(D9+E9+F9+G9)/4 -> 27624448 | J9: =((H9-I9)/I9)*100 -> -7.9448821 | K9: =('2020a'!J8+'2021a'!J8+'2022a'!J8+'2023a'!J9)/4 -> -4.1994223 | L9: =J9-K9 -> -3.7454598 | M9: -12 | N9: =M9+K9 -> -16.199422 | O9: =I9+((N9*I9)/100) -> 23149447 | P9: =H9 -> 25429719 | Q9: =ABS((O9-H9)/H9)*100 -> 8.9669542 | V9: =(O9-P9) -> -2280271.2
B10: 3. Maulid | C10: Monday, Sep 16 | D10: 30101526 | E10: 28313129 | F10: 28015138 | G10: 24826248 | H10: 24516279 | I10: =(D10+E10+F10+G10)/4 -> 27814010 | J10: =((H10-I10)/I10)*100 -> -11.856368 | K10: =('2020a'!J9+'2021a'!J9+'2022a'!J9+'2023a'!J10)/4 -> -7.4351604 | L10: =J10-K10 -> -4.421208 | M10: -13.6634 | N10: =M10+K10 -> -21.09856 | O10: =I10+((N10*I10)/100) -> 21945655 | P10: =H10 -> 24516279 | Q10: =ABS((O10-H10)/H10)*100 -> 10.485377 | V10: =(O10-P10) -> -2570624.2
B11: 4. Isra Mi'raj | C11: Thursday, Feb 08 | D11: 22303983 | E11: 29489179 | F11: 31781409 | G11: 29018457 | H11: 23904977 | I11: =(D11+E11+F11+G11)/4 -> 28148257 | J11: =((H11-I11)/I11)*100 -> -15.074752 | K11: =('2020a'!J10+'2021a'!J10+'2022a'!J10+'2023a'!J11)/4 -> -3.0757634 | L11: =J11-K11 -> -11.998988 | M11: -10.9342 | N11: =M11+K11 -> -14.009963 | O11: =I11+((N11*I11)/100) -> 24204697 | P11: =H11 -> 23904977 | Q11: =ABS((O11-H11)/H11)*100 -> 1.2537946 | V11: =(O11-P11) -> 299719.31
B12: 5. Idul Fitri I | C12: Saturday, Apr 10 | D12: 28929860 | E12: 23254492 | F12: 25535228 | G12: 22107167 | H12: 20221836 | I12: =(D12+E12+F12+G12)/4 -> 24956687 | J12: =((H12-I12)/I12)*100 -> -18.972272 | K12: =('2020a'!J11+'2021a'!J11+'2022a'!J11+'2023a'!J12)/4 -> -8.4619821 | L12: =J12-K12 -> -10.51029 | M12: 0 | N12: =M12+K12 -> -8.4619821 | O12: =I12+((N12*I12)/100) -> 22844857 | P12: =H12 -> 20221836 | Q12: =ABS((O12-H12)/H12)*100 -> 12.971226 | V12: =(O12-P12) -> 2623020.2
B13: 6. Idul Fitri II | C13: Sunday, Apr 11 | D13: 23254492 | E13: 25535228 | F13: 22107167 | G13: 20221836 | H13: 20717923 | I13: =(D13+E13+F13+G13)/4 -> 22779681 | J13: =((H13-I13)/I13)*100 -> -9.0508644 | K13: =('2020a'!J12+'2021a'!J12+'2022a'!J12+'2023a'!J13)/4 -> -2.6012736 | L13: =J13-K13 -> -6.4495908 | M13: -12 | N13: =M13+K13 -> -14.601274 | O13: =I13+((N13*I13)/100) -> 19453557 | P13: =H13 -> 20717923 | Q13: =ABS((O13-H13)/H13)*100 -> 6.1027619 | V13: =(O13-P13) -> -1264365.5
A14: Christian Holidays | B14: 1. Good Friday | C14: Friday, Mar 29 | D14: 33264637 | E14: 31685394 | F14: 32736843 | G14: 31201640 | H14: 25986092 | I14: =(D14+E14+F14+G14)/4 -> 32222128 | J14: =((H14-I14)/I14)*100 -> -19.353274 | K14: =('2020a'!J13+'2021a'!J13+'2022a'!J13+'2023a'!J14)/4 -> -10.471502 | L14: =J14-K14 -> -8.8817713 | M14: -14.0608 | N14: =M14+K14 -> -24.532302 | O14: =I14+((N14*I14)/100) -> 24317298 | P14: =H14 -> 25986092 | Q14: =ABS((O14-H14)/H14)*100 -> 6.4218709 | V14: =(O14-P14) -> -1668793.3
B15: 2. Ascension Day | C15: Thursday, May 09 | D15: 28258348 | E15: 30515259 | F15: 30187192 | G15: 28987478 | H15: 26009815 | I15: =(D15+E15+F15+G15)/4 -> 29487069 | J15: =((H15-I15)/I15)*100 -> -11.792473 | K15: =('2020a'!J14+'2021a'!J14+'2022a'!J14+'2023a'!J15)/4 -> -8.2612614 | L15: =J15-K15 -> -3.5312117 | M15: -7.9569 | N15: =M15+K15 -> -16.218161 | O15: =I15+((N15*I15)/100) -> 24704809 | P15: =H15 -> 26009815 | Q15: =ABS((O15-H15)/H15)*100 -> 5.017359 | V15: =(O15-P15) -> -1305005.8
B16: 3. Christmas | C16: Monday, Dec 25 | D16: 32988766 | E16: 31713502 | F16: 30089571 | G16: 23894817 | H16: 24792649 | I16: =(D16+E16+F16+G16)/4 -> 29671664 | J16: =((H16-I16)/I16)*100 -> -16.443348 | K16: =('2020a'!J15+'2021a'!J15+'2022a'!J15+'2023a'!J16)/4 -> -12.100568 | L16: =J16-K16 -> -4.3427803 | M16: 0 | N16: =M16+K16 -> -12.100568 | O16: =I16+((N16*I16)/100) -> 26081224 | P16: =H16 -> 24792649 | Q16: =ABS((O16-H16)/H16)*100 -> 5.1974083 | V16: =(O16-P16) -> 1288575.2
A17: Hindu, Buddhist, | B17: 1. Silent Day (Nyepi) | C17: Monday, Mar 11 | D17: 32770228 | E17: 30045391 | F17: 28826716 | G17: 22574331 | H17: 23546634 | I17: =(D17+E17+F17+G17)/4 -> 28554167 | J17: =((H17-I17)/I17)*100 -> -17.536958 | K17: =('2020a'!J16+'2021a'!J16+'2022a'!J16+'2023a'!J17)/4 -> -4.1531217 | L17: =J17-K17 -> -13.383836 | M17: -14.0186 | N17: =M17+K17 -> -18.171722 | O17: =I17+((N17*I17)/100) -> 23365383 | P17: =H17 -> 23546634 | Q17: =ABS((O17-H17)/H17)*100 -> 0.76975592 | V17: =(O17-P17) -> -181251.61
A18: and Chinese Holidays | B18: 2. Chinese New Year (Imlek) | C18: Saturday, Feb 10 | D18: 31781409 | E18: 29018457 | F18: 23904977 | G18: 24557871 | H18: 22710129 | I18: =(D18+E18+F18+G18)/4 -> 27315679 | J18: =((H18-I18)/I18)*100 -> -16.860463 | K18: =('2020a'!J17+'2021a'!J17+'2022a'!J17+'2023a'!J18)/4 -> -14.729437 | L18: =J18-K18 -> -2.1310256 | M18: -6.8104 | N18: =M18+K18 -> -21.539837 | O18: =I18+((N18*I18)/100) -> 21431926 | P18: =H18 -> 22710129 | Q18: =ABS((O18-H18)/H18)*100 -> 5.6283383 | V18: =(O18-P18) -> -1278202.9
B19: 3.Waisak | C19: Thursday, May 23 | D19: 23174758 | E19: 30251429 | F19: 29853482 | G19: 29008794 | H19: 25031136 | I19: =(D19+E19+F19+G19)/4 -> 28072116 | J19: =((H19-I19)/I19)*100 -> -10.832742 | K19: =('2020a'!J18+'2021a'!J18+'2022a'!J18+'2023a'!J19)/4 -> -6.7678605 | L19: =J19-K19 -> -4.0648817 | M19: 0 | N19: =M19+K19 -> -6.7678605 | O19: =I19+((N19*I19)/100) -> 26172234 | P19: =H19 -> 25031136 | Q19: =ABS((O19-H19)/H19)*100 -> 4.5587156 | V19: =(O19-P19) -> 1141098.3
P20: MAPE | Q20: =SUM(Q6:Q19)/14 -> 6.2938614 | R20: RMSE | S20: =SQRT(SUMXMY2(O6:O19, P6:P19) / COUNT(P6:P19)) -> 1671933.5 | T20: R2 | U20: =RSQ(O6:O19,P6:P19) -> 0.34856975 | V20: MAE | W20: {=AVERAGE(ABS(V6:V19))} -> 1497645.4 | X20: {=SUMPRODUCT(ABS(O6:O19 - P6:P19)) / COUNT(O6:O19)} -> 1497645.4
A22: Forecasting using Interval Type 2 Fuzzy Inference system
A23: Category | B23: Special Holiday | C23: Day / Date | D23: Day | I23: WDMAX | J23: LDMAX | K23: TLDMAX | L23: VLDMAX | M23: Output | N23: Forecast | O23: Peramalan | P23: Aktual | Q23: Error
D24: H-4 (Wh) | E24: H-3 (Wh) | F24: H-2 (Wh) | G24: H-1 (Wh) | H24: H (Wh) | M24: Forecast | N24: LDMAX | O24: P'MAX(Watthours) | P24: (Watthours) | Q24: (%)
A25: General Holidays | B25: 1. New Year | C25: Monday, Jan 01 | D25: 31962075 | E25: 31389832 | F25: 30887111 | G25: 27674659 | H25: 25001165 | I25: 30478419 | J25: -17.970926 | K25: -8.0090081 | L25: -9.9619177 | M25: -13.65 | N25: =M25+K25 -> -21.659008 | O25: =I25+((N25*I25)/100) -> 23877096 | P25: =H25 -> 25001165 | Q25: =ABS((O25-H25)/H25)*100 -> 4.4960672 | V25: =(O25-P25) -> -1124069.2
B26: 2. Independence Day | C26: Saturday, Aug 17 | D26: 27235140 | E26: 28261723 | F26: 29261318 | G26: 25243722 | H26: 24512818 | I26: 27500476 | J26: -10.864023 | K26: -7.2588762 | L26: -3.6051464 | M26: -8.627 | N26: =M26+K26 -> -15.885876 | O26: =I26+((N26*I26)/100) -> 23131784 | P26: =H26 -> 24512818 | Q26: =ABS((O26-H26)/H26)*100 -> 5.6339244 | V26: =(O26-P26) -> -1381033.6
A27: Islamic Holidays | B27: 1. Idul Adha | C27: Monday, Jun 17 | D27: 31957263 | E27: 31021032 | F27: 30016114 | G27: 25024126 | H27: 24126175 | I27: 29504634 | J27: -18.229199 | K27: -9.65528 | L27: -8.5739194 | M27: 0 | N27: =M27+K27 -> -9.65528 | O27: =I27+((N27*I27)/100) -> 26655879 | P27: =H27 -> 24126175 | Q27: =ABS((O27-H27)/H27)*100 -> 10.485307 | V27: =(O27-P27) -> 2529703.5
B28: 2. Islamic New Year | C28: Sunday, Jul 07 | D28: 30050153 | E28: 26598716 | F28: 26845796 | G28: 27003129 | H28: 25429719 | I28: 27624448 | J28: -7.9448821 | K28: -4.1994223 | L28: -3.7454598 | M28: -12 | N28: =M28+K28 -> -16.199422 | O28: =I28+((N28*I28)/100) -> 23149447 | P28: =H28 -> 25429719 | Q28: =ABS((O28-H28)/H28)*100 -> 8.9669542 | V28: =(O28-P28) -> -2280271.2
B29: 3. Maulid | C29: Monday, Sep 16 | D29: 30101526 | E29: 28313129 | F29: 28015138 | G29: 24826248 | H29: 24516279 | I29: 27814010 | J29: -11.856368 | K29: -7.4351604 | L29: -4.421208 | M29: -13.65 | N29: =M29+K29 -> -21.08516 | O29: =I29+((N29*I29)/100) -> 21949382 | P29: =H29 -> 24516279 | Q29: =ABS((O29-H29)/H29)*100 -> 10.470174 | V29: =(O29-P29) -> -2566897.2
B30: 4. Isra Mi'raj | C30: Thursday, Feb 08 | D30: 22303983 | E30: 29489179 | F30: 31781409 | G30: 29018457 | H30: 23904977 | I30: 28148257 | J30: -15.074752 | K30: -3.0757634 | L30: -11.998988 | M30: -10.5 | N30: =M30+K30 -> -13.575763 | O30: =I30+((N30*I30)/100) -> 24326916 | P30: =H30 -> 23904977 | Q30: =ABS((O30-H30)/H30)*100 -> 1.7650677 | V30: =(O30-P30) -> 421939.04
B31: 5. Idul Fitri I | C31: Saturday, Apr 10 | D31: 28929860 | E31: 23254492 | F31: 25535228 | G31: 22107167 | H31: 20221836 | I31: 24956687 | J31: -18.972272 | K31: -8.4619821 | L31: -10.51029 | M31: 0 | N31: =M31+K31 -> -8.4619821 | O31: =I31+((N31*I31)/100) -> 22844857 | P31: =H31 -> 20221836 | Q31: =ABS((O31-H31)/H31)*100 -> 12.971226 | V31: =(O31-P31) -> 2623020.2
B32: 6. Idul Fitri II | C32: Sunday, Apr 11 | D32: 23254492 | E32: 25535228 | F32: 22107167 | G32: 20221836 | H32: 20717923 | I32: 22779681 | J32: -9.0508644 | K32: -2.6012736 | L32: -6.4495908 | M32: -12 | N32: =M32+K32 -> -14.601274 | O32: =I32+((N32*I32)/100) -> 19453557 | P32: =H32 -> 20717923 | Q32: =ABS((O32-H32)/H32)*100 -> 6.1027619 | V32: =(O32-P32) -> -1264365.5
A33: Christian Holidays | B33: 1. Good Friday | C33: Friday, Mar 29 | D33: 33264637 | E33: 31685394 | F33: 32736843 | G33: 31201640 | H33: 25986092 | I33: 32222128 | J33: -19.353274 | K33: -10.471502 | L33: -8.8817713 | M33: -14.2775 | N33: =M33+K33 -> -24.749002 | O33: =I33+((N33*I33)/100) -> 24247473 | P33: =H33 -> 25986092 | Q33: =ABS((O33-H33)/H33)*100 -> 6.6905737 | V33: =(O33-P33) -> -1738618.6
B34: 2. Ascension Day | C34: Thursday, May 09 | D34: 28258348 | E34: 30515259 | F34: 30187192 | G34: 28987478 | H34: 26009815 | I34: 29487069 | J34: -11.792473 | K34: -8.2612614 | L34: -3.5312117 | M34: -7.3544 | N34: =M34+K34 -> -15.615661 | O34: =I34+((N34*I34)/100) -> 24882469 | P34: =H34 -> 26009815 | Q34: =ABS((O34-H34)/H34)*100 -> 4.3343108 | V34: =(O34-P34) -> -1127346.2
B35: 3. Christmas | C35: Monday, Dec 25 | D35: 32988766 | E35: 31713502 | F35: 30089571 | G35: 23894817 | H35: 24792649 | I35: 29671664 | J35: -16.443348 | K35: -12.100568 | L35: -4.3427803 | M35: 0 | N35: =M35+K35 -> -12.100568 | O35: =I35+((N35*I35)/100) -> 26081224 | P35: =H35 -> 24792649 | Q35: =ABS((O35-H35)/H35)*100 -> 5.1974083 | V35: =(O35-P35) -> 1288575.2
A36: Hindu, Buddhist, | B36: 1. Silent Day (Nyepi) | C36: Monday, Mar 11 | D36: 32770228 | E36: 30045391 | F36: 28826716 | G36: 22574331 | H36: 23546634 | I36: 28554167 | J36: -17.536958 | K36: -4.1531217 | L36: -13.383836 | M36: -14.2091 | N36: =M36+K36 -> -18.362222 | O36: =I36+((N36*I36)/100) -> 23310987 | P36: =H36 -> 23546634 | Q36: =ABS((O36-H36)/H36)*100 -> 1.0007685 | V36: =(O36-P36) -> -235647.3
A37: and Chinese Holidays | B37: 2. Chinese New Year (Imlek) | C37: Saturday, Feb 10 | D37: 31781409 | E37: 29018457 | F37: 23904977 | G37: 24557871 | H37: 22710129 | I37: 27315679 | J37: -16.860463 | K37: -14.729437 | L37: -2.1310256 | M37: -6 | N37: =M37+K37 -> -20.729437 | O37: =I37+((N37*I37)/100) -> 21653292 | P37: =H37 -> 22710129 | Q37: =ABS((O37-H37)/H37)*100 -> 4.6535914 | V37: =(O37-P37) -> -1056836.6
B38: 3.Waisak | C38: Thursday, May 23 | D38: 23174758 | E38: 30251429 | F38: 29853482 | G38: 29008794 | H38: 25031136 | I38: 28072116 | J38: -10.832742 | K38: -6.7678605 | L38: -4.0648817 | M38: 0 | N38: =M38+K38 -> -6.7678605 | O38: =I38+((N38*I38)/100) -> 26172234 | P38: =H38 -> 25031136 | Q38: =ABS((O38-H38)/H38)*100 -> 4.5587156 | V38: =(O38-P38) -> 1141098.3
P39: MAPE | Q39: =SUM(Q25:Q38)/14 -> 6.2376323 | R39: RMSE | S39: =SQRT(SUMXMY2(O25:O38, P25:P38) / COUNT(P25:P38)) -> 1657113.2 | T39: R2 | U39: =RSQ(O25:O38,P25:P38) -> 0.35081363 | V39: MAE | W39: {=AVERAGE(ABS(V25:V38))} -> 1484244.4 | X39: {=SUMPRODUCT(ABS(O25:O38 - P25:P38)) / COUNT(O25:O38)} -> 1484244.4
A41: Forecasting using IT2FIS-CSA
A42: Category | B42: Special Holiday | C42: Day / Date | D42: Day | I42: WDMAX | J42: LDMAX | K42: TLDMAX | L42: VLDMAX | M42: Output | N42: Forecast | O42: Peramalan | P42: Aktual | Q42: Error
D43: H-4 (Wh) | E43: H-3 (Wh) | F43: H-2 (Wh) | G43: H-1 (Wh) | H43: H (Wh) | M43: Forecast | N43: LDMAX | O43: P'MAX(Watthours) | P43: (Watthours) | Q43: (%)
...

Sheet Result VLD 2024
B1: RESULT FORCASTING VLD TAHUN 2024
B3: Type-1 | E3: IT2-FIS | H3: IT2FIS-CSA | K3: IT2FIS-FA | N3: IT2FIS-ZOA | Q3: IT2FIS-OOA
B4: Actual | C4: Forecast | D4: Error | E4: Actual | F4: Forecast | G4: Error | H4: Actual | I4: Forecast | J4: Error | K4: Actual | L4: Forecast | M4: Error | N4: Actual | O4: Forecast | P4: Error | Q4: Actual | R4: Forecast | S4: Error
B5: ='2024a'!L6 -> -9.9619177 | C5: ='2024a'!M6 -> -13.7527 | D5: =ABS(B5-C5) -> 3.7907823 | E5: ='2024a'!L25 -> -9.9619177 | F5: ='2024a'!M25 -> -13.65 | G5: =ABS(E5-F5) -> 3.6880823 | H5: ='2024a'!L44 -> -9.9619177 | I5: ='2024a'!M44 -> -13.65 | J5: =ABS(H5-I5) -> 3.6880823 | K5: ='2024a'!L63 -> -9.9619177 | L5: ='2024a'!M63 -> -13.65 | M5: =ABS(K5-L5) -> 3.6880823 | N5: ='2024a'!L82 -> -9.9619177 | O5: ='2024a'!M82 -> -13.65 | P5: =ABS(N5-O5) -> 3.6880823 | Q5: ='2024a'!L102 -> -9.9619177 | R5: ='2024a'!M102 -> -13.65 | S5: =ABS(Q5-R5) -> 3.6880823
B6: ='2024a'!L7 -> -3.6051464 | C6: ='2024a'!M7 -> -8.627 | D6: =ABS(B6-C6) -> 5.0218536 | E6: ='2024a'!L26 -> -3.6051464 | F6: ='2024a'!M26 -> -8.627 | G6: =ABS(E6-F6) -> 5.0218536 | H6: ='2024a'!L45 -> -3.6051464 | I6: ='2024a'!M45 -> -8.627 | J6: =ABS(H6-I6) -> 5.0218536 | K6: ='2024a'!L64 -> -3.6051464 | L6: ='2024a'!M64 -> -8.627 | M6: =ABS(K6-L6) -> 5.0218536 | N6: ='2024a'!L83 -> -3.6051464 | O6: ='2024a'!M83 -> -8.627 | P6: =ABS(N6-O6) -> 5.0218536 | Q6: ='2024a'!L103 -> -3.6051464 | R6: ='2024a'!M103 -> -8.627 | S6: =ABS(Q6-R6) -> 5.0218536
B7: ='2024a'!L8 -> -8.5739194 | C7: ='2024a'!M8 -> 0 | D7: =ABS(B7-C7) -> 8.5739194 | E7: ='2024a'!L27 -> -8.5739194 | F7: ='2024a'!M27 -> 0 | G7: =ABS(E7-F7) -> 8.5739194 | H7: ='2024a'!L46 -> -8.5739194 | I7: ='2024a'!M46 -> 0 | J7: =ABS(H7-I7) -> 8.5739194 | K7: ='2024a'!L65 -> -8.5739194 | L7: ='2024a'!M65 -> 0 | M7: =ABS(K7-L7) -> 8.5739194 | N7: ='2024a'!L84 -> -8.5739194 | O7: ='2024a'!M84 -> 0 | P7: =ABS(N7-O7) -> 8.5739194 | Q7: ='2024a'!L104 -> -8.5739194 | R7: ='2024a'!M104 -> 0 | S7: =ABS(Q7-R7) -> 8.5739194
B8: ='2024a'!L9 -> -3.7454598 | C8: ='2024a'!M9 -> -12 | D8: =ABS(B8-C8) -> 8.2545402 | E8: ='2024a'!L28 -> -3.7454598 | F8: ='2024a'!M28 -> -12 | G8: =ABS(E8-F8) -> 8.2545402 | H8: ='2024a'!L47 -> -3.7454598 | I8: ='2024a'!M47 -> -11.9902 | J8: =ABS(H8-I8) -> 8.2447402 | K8: ='2024a'!L66 -> -3.7454598 | L8: ='2024a'!M66 -> -11.9474 | M8: =ABS(K8-L8) -> 8.2019402 | N8: ='2024a'!L85 -> -3.7454598 | O8: ='2024a'!M85 -> -11.9858 | P8: =ABS(N8-O8) -> 8.2403402 | Q8: ='2024a'!L105 -> -3.7454598 | R8: ='2024a'!M105 -> -11.9869 | S8: =ABS(Q8-R8) -> 8.2414402
B9: ='2024a'!L10 -> -4.421208 | C9: ='2024a'!M10 -> -13.6634 | D9: =ABS(B9-C9) -> 9.242192 | E9: ='2024a'!L29 -> -4.421208 | F9: ='2024a'!M29 -> -13.65 | G9: =ABS(E9-F9) -> 9.228792 | H9: ='2024a'!L48 -> -4.421208 | I9: ='2024a'!M48 -> -13.65 | J9: =ABS(H9-I9) -> 9.228792 | K9: ='2024a'!L67 -> -4.421208 | L9: ='2024a'!M67 -> -13.65 | M9: =ABS(K9-L9) -> 9.228792 | N9: ='2024a'!L86 -> -4.421208 | O9: ='2024a'!M86 -> -13.65 | P9: =ABS(N9-O9) -> 9.228792 | Q9: ='2024a'!L106 -> -4.421208 | R9: ='2024a'!M106 -> -13.65 | S9: =ABS(Q9-R9) -> 9.228792
B10: ='2024a'!L11 -> -11.998988 | C10: ='2024a'!M11 -> -10.9342 | D10: =ABS(B10-C10) -> 1.0647882 | E10: ='2024a'!L30 -> -11.998988 | F10: ='2024a'!M30 -> -10.5 | G10: =ABS(E10-F10) -> 1.4989882 | H10: ='2024a'!L49 -> -11.998988 | I10: ='2024a'!M49 -> -10.5 | J10: =ABS(H10-I10) -> 1.4989882 | K10: ='2024a'!L68 -> -11.998988 | L10: ='2024a'!M68 -> -10.5 | M10: =ABS(K10-L10) -> 1.4989882 | N10: ='2024a'!L87 -> -11.998988 | O10: ='2024a'!M87 -> -10.5 | P10: =ABS(N10-O10) -> 1.4989882 | Q10: ='2024a'!L107 -> -11.998988 | R10: ='2024a'!M107 -> -10.798 | S10: =ABS(Q10-R10) -> 1.2009882
B11: ='2024a'!L12 -> -10.51029 | C11: ='2024a'!M12 -> 0 | D11: =ABS(B11-C11) -> 10.51029 | E11: ='2024a'!L31 -> -10.51029 | F11: ='2024a'!M31 -> 0 | G11: =ABS(E11-F11) -> 10.51029 | H11: ='2024a'!L50 -> -10.51029 | I11: ='2024a'!M50 -> 0 | J11: =ABS(H11-I11) -> 10.51029 | K11: ='2024a'!L69 -> -10.51029 | L11: ='2024a'!M69 -> 0 | M11: =ABS(K11-L11) -> 10.51029 | N11: ='2024a'!L88 -> -10.51029 | O11: ='2024a'!M88 -> 0 | P11: =ABS(N11-O11) -> 10.51029 | Q11: ='2024a'!L108 -> -10.51029 | R11: ='2024a'!M108 -> 0 | S11: =ABS(Q11-R11) -> 10.51029
B12: ='2024a'!L13 -> -6.4495908 | C12: ='2024a'!M13 -> -12 | D12: =ABS(B12-C12) -> 5.5504092 | E12: ='2024a'!L32 -> -6.4495908 | F12: ='2024a'!M32 -> -12 | G12: =ABS(E12-F12) -> 5.5504092 | H12: ='2024a'!L51 -> -6.4495908 | I12: ='2024a'!M51 -> -12 | J12: =ABS(H12-I12) -> 5.5504092 | K12: ='2024a'!L70 -> -6.4495908 | L12: ='2024a'!M70 -> -12 | M12: =ABS(K12-L12) -> 5.5504092 | N12: ='2024a'!L89 -> -6.4495908 | O12: ='2024a'!M89 -> -12 | P12: =ABS(N12-O12) -> 5.5504092 | Q12: ='2024a'!L109 -> -6.4495908 | R12: ='2024a'!M109 -> -12 | S12: =ABS(Q12-R12) -> 5.5504092
B13: ='2024a'!L14 -> -8.8817713 | C13: ='2024a'!M14 -> -14.0608 | D13: =ABS(B13-C13) -> 5.1790287 | E13: ='2024a'!L33 -> -8.8817713 | F13: ='2024a'!M33 -> -14.2775 | G13: =ABS(E13-F13) -> 5.3957287 | H13: ='2024a'!L52 -> -8.8817713 | I13: ='2024a'!M52 -> -14.3108 | J13: =ABS(H13-I13) -> 5.4290287 | K13: ='2024a'!L71 -> -8.8817713 | L13: ='2024a'!M71 -> -14.277 | M13: =ABS(K13-L13) -> 5.3952287 | N13: ='2024a'!L90 -> -8.8817713 | O13: ='2024a'!M90 -> -14.2835 | P13: =ABS(N13-O13) -> 5.4017287 | Q13: ='2024a'!L110 -> -8.8817713 | R13: ='2024a'!M110 -> -14.2682 | S13: =ABS(Q13-R13) -> 5.3864287
B14: ='2024a'!L15 -> -3.5312117 | C14: ='2024a'!M15 -> -7.9569 | D14: =ABS(B14-C14) -> 4.4256883 | E14: ='2024a'!L34 -> -3.5312117 | F14: ='2024a'!M34 -> -7.3544 | G14: =ABS(E14-F14) -> 3.8231883 | H14: ='2024a'!L53 -> -3.5312117 | I14: ='2024a'!M53 -> -7.3342 | J14: =ABS(H14-I14) -> 3.8029883 | K14: ='2024a'!L72 -> -3.5312117 | L14: ='2024a'!M72 -> -7.3463 | M14: =ABS(K14-L14) -> 3.8150883 | N14: ='2024a'!L91 -> -3.5312117 | O14: ='2024a'!M91 -> -7.2103 | P14: =ABS(N14-O14) -> 3.6790883 | Q14: ='2024a'!L111 -> -3.5312117 | R14: ='2024a'!M111 -> -7.2055 | S14: =ABS(Q14-R14) -> 3.6742883
B15: ='2024a'!L16 -> -4.3427803 | C15: ='2024a'!M16 -> 0 | D15: =ABS(B15-C15) -> 4.3427803 | E15: ='2024a'!L35 -> -4.3427803 | F15: ='2024a'!M35 -> 0 | G15: =ABS(E15-F15) -> 4.3427803 | H15: ='2024a'!L54 -> -4.3427803 | I15: ='2024a'!M54 -> 0 | J15: =ABS(H15-I15) -> 4.3427803 | K15: ='2024a'!L73 -> -4.3427803 | L15: ='2024a'!M73 -> 0 | M15: =ABS(K15-L15) -> 4.3427803 | N15: ='2024a'!L92 -> -4.3427803 | O15: ='2024a'!M92 -> 0 | P15: =ABS(N15-O15) -> 4.3427803 | Q15: ='2024a'!L112 -> -4.3427803 | R15: ='2024a'!M112 -> 0 | S15: =ABS(Q15-R15) -> 4.3427803
B16: ='2024a'!L17 -> -13.383836 | C16: ='2024a'!M17 -> -14.0186 | D16: =ABS(B16-C16) -> 0.63476415 | E16: ='2024a'!L36 -> -13.383836 | F16: ='2024a'!M36 -> -14.2091 | G16: =ABS(E16-F16) -> 0.82526415 | H16: ='2024a'!L55 -> -13.383836 | I16: ='2024a'!M55 -> -14.2233 | J16: =ABS(H16-I16) -> 0.83946415 | K16: ='2024a'!L74 -> -13.383836 | L16: ='2024a'!M74 -> -14.1039 | M16: =ABS(K16-L16) -> 0.72006415 | N16: ='2024a'!L93 -> -13.383836 | O16: ='2024a'!M93 -> -14.2132 | P16: =ABS(N16-O16) -> 0.82936415 | Q16: ='2024a'!L113 -> -13.383836 | R16: ='2024a'!M113 -> -14.1794 | S16: =ABS(Q16-R16) -> 0.79556415
... B18: ='2024a'!L19 -> -4.0648817 | C18: ='2024a'!M19 -> 0 | D18: =ABS(B18-C18) -> 4.0648817 | E18: ='2024a'!L38 -> -4.0648817 | F18: ='2024a'!M38 -> 0 | G18: =ABS(E18-F18) -> 4.0648817 | H18: ='2024a'!L57 -> -4.0648817 | I18: ='2024a'!M57 -> 0 | J18: =ABS(H18-I18) -> 4.0648817 | K18: ='2024a'!L76 -> -4.0648817 | L18: ='2024a'!M76 -> 0 | M18: =ABS(K18-L18) -> 4.0648817 | N18: ='2024a'!L95 -> -4.0648817 | O18: ='2024a'!M95 -> 0 | P18: =ABS(N18-O18) -> 4.0648817 | Q18: ='2024a'!L115 -> -4.0648817 | R18: ='2024a'!M115 -> 0 | S18: =ABS(Q18-R18) -> 4.0648817

Sheet VLD(x,y,z)2022
A1: Input (X,Y) dan output (Z) VLDMAX year 2022
A3: Category | B3: Special Holiday | D3: 2021 | E3: 2022 | F3: Input | H3: Output
D4: VLDMAX | E4: VLDMAX | F4: X | G4: Y | H4: Z
A5: General Holidays | B5: 1. New Year | D5: ='2021a'!L5 -> -0.37383879 | E5: ='2022a'!L5 -> -0.48006314 | F5: =D5 -> -0.37383879 | G5: =E6 -> -6.094273 | H5: =E5 -> -0.48006314
B6: 2. Independence Day | D6: ='2021a'!L6 -> -3.8646589 | E6: ='2022a'!L6 -> -6.094273 | F6: =D6 -> -3.8646589 | G6: =E5 -> -0.48006314 | H6: =E6 -> -6.094273
A7: Islamic Holidays | B7: 1. Idul Adha | D7: ='2021a'!L7 -> -2.3990196 | E7: ='2022a'!L7 -> -9.9893364 | F7: =D7 -> -2.3990196 | G7: =E12 -> -3.6756394 | H7: =E7 -> -9.9893364
B8: 2. Islamic New Year | D8: ='2021a'!L8 -> -0.44835353 | E8: ='2022a'!L8 -> -11.538678 | F8: =D8 -> -0.44835353 | G8: =E7 -> -9.9893364 | H8: =E8 -> -11.538678
B9: 3. Maulid | D9: ='2021a'!L9 -> -8.1964196 | E9: ='2022a'!L9 -> -10.187522 | F9: =D9 -> -8.1964196 | G9: =E8 -> -11.538678 | H9: =E9 -> -10.187522
B10: 4. Isra Mi'raj | D10: ='2021a'!L10 -> -5.5194506 | E10: ='2022a'!L10 -> -4.6052368 | F10: =D10 -> -5.5194506 | G10: =E9 -> -10.187522 | H10: =E10 -> -4.6052368
B11: 5. Idul Fitri I | D11: ='2021a'!L11 -> -4.9303841 | E11: ='2022a'!L11 -> -9.8900317 | F11: =D11 -> -4.9303841 | G11: =E10 -> -4.6052368 | H11: =E11 -> -9.8900317
B12: 6. Idul Fitri II | D12: ='2021a'!L12 -> -7.056827 | E12: ='2022a'!L12 -> -3.6756394 | F12: =D12 -> -7.056827 | G12: =E11 -> -9.8900317 | H12: =E12 -> -3.6756394
A13: Christian Holidays | B13: 1. Good Friday | D13: ='2021a'!L13 -> -9.8409322 | E13: ='2022a'!L13 -> -6.5432734 | F13: =D13 -> -9.8409322 | G13: =E14 -> -6.8268972 | H13: =E13 -> -6.5432734
B14: 2. Ascension Day | D14: ='2021a'!L14 -> 1.1225287 | E14: ='2022a'!L14 -> -6.8268972 | F14: =D14 -> 1.1225287 | G14: =E13 -> -6.5432734 | H14: =E14 -> -6.8268972
B15: 3. Christmas | D15: ='2021a'!L15 -> -13.795958 | E15: ='2022a'!L15 -> -4.0278267 | F15: =D15 -> -13.795958 | G15: =E14 -> -6.8268972 | H15: =E15 -> -4.0278267
A16: Hindu, Buddhist, | B16: 1. Silent Day (Nyepi) | D16: ='2021a'!L16 -> -6.0804868 | E16: ='2022a'!L16 -> 13.646953 | F16: =D16 -> -6.0804868 | G16: =E17 -> 9.5011013 | H16: =E16 -> 13.646953
A17: and Chinese Holidays | B17: 2. Chinese New Year (Imlek) | D17: ='2021a'!L17 -> 7.8761851 | E17: ='2022a'!L17 -> 9.5011013 | F17: =D17 -> 7.8761851 | G17: =E16 -> 13.646953 | H17: =E17 -> 9.5011013
B18: 3. Waisak | D18: ='2021a'!L18 -> 5.2214559 | E18: ='2022a'!L18 -> -6.9784191 | F18: =D18 -> 5.2214559 | G18: =E17 -> 9.5011013 | H18: =E18 -> -6.9784191
A22: Rule Base for Input X year 2022
A24: Category | B24: Special Holiday | C24: Value | D24: Membership Degree (μ) | O24: Rule
C25: X | D25: NVB | E25: NB | F25: NM | G25: NS | H25: NVS | I25: ZE | J25: PVS | K25: PS | L25: PM | M25: PB | N25: PVB | O25: X
A26: General Holidays | B26: 1. New Year | C26: =F5 -> -0.37383879 | H26: =-(C26)/3 -> 0.12461293 | I26: =(C26+3)/3 -> 0.87538707 | O26: ZE
B27: 2. Independence Day | C27: =F6 -> -3.8646589 | G27: =(-3-C27)/3 -> 0.28821964 | H27: =(C27+6)/3 -> 0.71178036 | O27: NVS
A28: Islamic Holidays | B28: 1. Idul Adha | C28: =F7 -> -2.3990196 | H28: =-(C28)/3 -> 0.79967319 | I28: =(C28+3)/3 -> 0.20032681 | O28: NVS
B29: 2. Islamic New Year | C29: =F8 -> -0.44835353 | H29: =-(C29)/3 -> 0.14945118 | I29: =(C29+3)/3 -> 0.85054882 | O29: ZE
B30: 3. Maulid | C30: =F9 -> -8.1964196 | F30: =(-6-(C30))/3 -> 0.73213987 | G30: =(C30+9)/3 -> 0.26786013 | O30: NM
B31: 4. Isra Mi'raj | C31: =F10 -> -5.5194506 | G31: =(-3-C31)/3 -> 0.83981686 | H31: =(C31+6)/3 -> 0.16018314 | O31: NS
B32: 5. Idul Fitri I | C32: =F11 -> -4.9303841 | G32: =(-3-C32)/3 -> 0.64346135 | H32: =(C32+6)/3 -> 0.35653865 | O32: NS
B33: 6. Idul Fitri II | C33: =F12 -> -7.056827 | F33: =(-6-(C33))/3 -> 0.35227566 | G33: =(C33+9)/3 -> 0.64772434 | O33: NS
A34: Christian Holidays | B34: 1. Good Friday | C34: =F13 -> -9.8409322 | E34: =(-9-C34)/3 -> 0.28031074 | F34: =(C34+12)/3 -> 0.71968926 | O34: NM
B35: 2. Ascension Day | C35: =F14 -> 1.1225287 | I35: =(3-C35)/3 -> 0.62582377 | J35: =C35/3 -> 0.37417623 | O35: ZE
B36: 3. Christmas | C36: =F15 -> -13.795958 | D36: =(-12-C36)/3 -> 0.59865251 | E36: =(C36+15)/3 -> 0.40134749 | O36: NVB
A37: Hindu, Buddhist, | B37: 1. Silent Day (Nyepi) | C37: =F16 -> -6.0804868 | F37: =(-6-(C37))/3 -> 0.026828934 | G37: =(C37+9)/3 -> 0.97317107 | O37: NS
A38: and Chinese Holidays | B38: 2. Chinese New Year (Imlek) | C38: =F17 -> 7.8761851 | K38: =(9-C38)/3 -> 0.37460498 | L38: =(C38-6)/3 -> 0.62539502 | O38: PM
B39: 3. Waisak | C39: =F18 -> 5.2214559 | J39: =(6-C39)/3 -> 0.25951469 | K39: =(C39-3)/3 -> 0.74048531 | O39: PS
A43: Rule Base for Input Y year 2022
A45: Category | B45: Special Holiday | C45: Value | D45: Membership Degree (μ) | O45: Rule
C46: Y | D46: NVB | E46: NB | F46: NM | G46: NS | H46: NVS | I46: ZE | J46: PVS | K46: PS | L46: PM | M46: PB | N46: PVB | O46: Y
