Workbook

Sheet 2020a
A1: Konsumsi Beban RSUD ULIN Hari-hari Libur Tahun 2020
A3: Kelompok | B3: Nama Hari Libur | C3: Hari | D3: Hari Ke | I3: WDMAX | J3: LDMAX
C4: Tanggal | D4: H-4 | E4: H-3 | F4: H-2 | G4: H-1 | H4: H
A5: Hari Libur | B5: 1.Tahun Baru Masehi | C5: Rabu/ 01 Januari | D5: 21584538 | E5: 22686539 | F5: 23612437 | G5: 26977415 | H5: 22567256 | I5: =(D5+E5+F5+G5)/4 -> 23715232 | J5: =((H5-I5)/I5)*100 -> -4.8406691
A6: Umum | B6: 2.Proklamasi Kemerdekaan RI | C6: Senin / 17 Agustus | D6: 25800705 | E6: 24137737 | F6: 23092416 | G6: 21587126 | H6: 23420438 | I6: =(D6+E6+F6+G6)/4 -> 23654496 | J6: =((H6-I6)/I6)*100 -> -0.98948546
A7: Hari Raya | B7: 1.Idul Adha | C7: Jumat / 31 Juli | D7: 23826316 | E7: 20324142 | F7: 22423342 | G7: 21423342 | H7: 21625342 | I7: =(D7+E7+F7+G7)/4 -> 21999285 | J7: =((H7-I7)/I7)*100 -> -1.6997987
A8: Islam | B8: 2.Tahun Baru Hijriyah | C8: Kamis / 20 Agustus | D8: 22587125 | E8: 23998476 | F8: 22757125 | G8: 23689126 | H8: 23812488 | I8: =(D8+E8+F8+G8)/4 -> 23257963 | J8: =((H8-I8)/I8)*100 -> 2.3842395
B9: 3.Maulid Nabi Muhammad SAW | C9: Kamis / 29 Oktober | D9: 26102310 | E9: 26567257 | F9: 25763257 | G9: 26363240 | H9: 26978630 | I9: =(D9+E9+F9+G9)/4 -> 26199016 | J9: =((H9-I9)/I9)*100 -> 2.9757394
B10: 4.Isra Mi'raj | C10: Minggu / 22 Maret | D10: 24520981 | E10: 25901645 | F10: 24987811 | G10: 26006907 | H10: 25901645 | I10: =(D10+E10+F10+G10)/4 -> 25354336 | J10: =((H10-I10)/I10)*100 -> 2.1586407
B11: 5.Idul Fitri I | C11: Minggu / 24 Mei | D11: 22151895 | E11: 22742761 | F11: 23242825 | G11: 22572630 | H11: 22949802 | I11: =(D11+E11+F11+G11)/4 -> 22677528 | J11: =((H11-I11)/I11)*100 -> 1.2006336
B12: 6.Idul Fitri II | C12: Senin / 25 Mei | D12: 22742761 | E12: 23242825 | F12: 22572630 | G12: 22949802 | H12: 23457313 | I12: =(D12+E12+F12+G12)/4 -> 22877005 | J12: =((H12-I12)/I12)*100 -> 2.5366439
A13: Hari Raya | B13: 1.Wafatnya Isa Almasih | C13: Jumat/ 10 April | D13: 22224364 | E13: 24161370 | F13: 23302242 | G13: 23273985 | H13: 23007013 | I13: =(D13+E13+F13+G13)/4 -> 23240490 | J13: =((H13-I13)/I13)*100 -> -1.0046133
A14: Kristen | B14: 2.Kenaikan Isa Almasih | C14: Kamis/ 21 Mei | D14: 23000644 | E14: 27058926 | F14: 23398859 | G14: 22151895 | H14: 22742761 | I14: =(D14+E14+F14+G14)/4 -> 23902581 | J14: =((H14-I14)/I14)*100 -> -4.8522791
B15: 3.Natal | C15: Jumat / 25 Desember | D15: 25465122 | E15: 26931676 | F15: 24803189 | G15: 25181154 | H15: 25456620 | I15: =(D15+E15+F15+G15)/4 -> 25595285 | J15: =((H15-I15)/I15)*100 -> -0.54176009
A16: Hari Raya | B16: 1.Nyepi | C16: Rabu / 25 Maret | D16: 26006907 | E16: 25901645 | F16: 25002606 | G16: 24801785 | H16: 24601645 | I16: =(D16+E16+F16+G16)/4 -> 25428236 | J16: =((H16-I16)/I16)*100 -> -3.2506805
A17: Hindu / | B17: 2.Tahun Baru Imlek | C17: Sabtu / 25 Januari | D17: 28134040 | E17: 29372832 | F17: 29493308 | G17: 27138620 | H17: 23110877 | I17: =(D17+E17+F17+G17)/4 -> 28534700 | J17: =((H17-I17)/I17)*100 -> -19.007814
A18: Budha/ | B18: 3.Waisak | C18: Kamis / 07 Mei | D18: 23398859 | E18: 21973606 | F18: 22838017 | G18: 22732675 | H18: 22035484 | I18: =(D18+E18+F18+G18)/4 -> 22735789 | J18: =((H18-I18)/I18)*100 -> -3.0801889
A19: Tionghoa

Sheet 2021a
A1: Konsumsi Beban RSUD ULIN Hari-hari Libur Tahun 2021
A3: Kelompok | B3: Nama Hari Libur | C3: Hari | D3: Hari Ke | I3: WDMAX | J3: LDMAX
C4: Tanggal | D4: H-4 | E4: H-3 | F4: H-2 | G4: H-1 | H4: H
A5: Hari Libur | B5: 1.Tahun Baru Masehi | C5: Jumat / 01 Januari | D5: 26362121 | E5: 24633072 | F5: 25633792 | G5: 23463371 | H5: 23718258 | I5: =(D5+E5+F5+G5)/4 -> 25023089 | J5: =((H5-I5)/I5)*100 -> -5.2145079
A6: Umum | B6: 2.Proklamasi Kemerdekaan RI | C6: Selasa / 17 Agustus | D6: 24464888 | E6: 25477371 | F6: 23241235 | G6: 25411914 | H6: 23452361 | I6: =(D6+E6+F6+G6)/4 -> 24648852 | J6: =((H6-I6)/I6)*100 -> -4.8541444
A7: Hari Raya | B7: 1.Idul Adha | C7: Selasa / 20 Juli | D7: 23442566 | E7: 23481886 | F7: 21702795 | G7: 25998747 | H7: 22686862 | I7: =(D7+E7+F7+G7)/4 -> 23656498 | J7: =((H7-I7)/I7)*100 -> -4.0988182
A8: Islam | B8: 2.Tahun Baru Hijriyah | C8: Selasa / 10 Agustus | D8: 25064032 | E8: 25622147 | F8: 23650703 | G8: 23507110 | H8: 24934535 | I8: =(D8+E8+F8+G8)/4 -> 24460998 | J8: =((H8-I8)/I8)*100 -> 1.935886
B9: 3.Maulid Nabi Muhammad SAW | C9: Selasa / 19 Oktober | D9: 28519671 | E9: 29260420 | F9: 30285710 | G9: 27039562 | H9: 27274020 | I9: =(D9+E9+F9+G9)/4 -> 28776341 | J9: =((H9-I9)/I9)*100 -> -5.2206802
B10: 4.Isra Mi'raj | C10: Kamis / 11 Maret | D10: 23979209 | E10: 24342530 | F10: 26026584 | G10: 26684617 | H10: 24409354 | I10: =(D10+E10+F10+G10)/4 -> 25258235 | J10: =((H10-I10)/I10)*100 -> -3.3608099
B11: 5.Idul Fitri I | C11: Kamis / 13 Mei | D11: 24755826 | E11: 24872874 | F11: 25198627 | G11: 24279438 | H11: 23852583 | I11: =(D11+E11+F11+G11)/4 -> 24776692 | J11: =((H11-I11)/I11)*100 -> -3.7297504
B12: 6.Idul Fitri II | C12: Jumat / 14 Mei | D12: 24872874 | E12: 25198627 | F12: 24279438 | G12: 23852583 | H12: 23441136 | I12: =(D12+E12+F12+G12)/4 -> 24550881 | J12: =((H12-I12)/I12)*100 -> -4.520183
A13: Hari Raya | B13: 1.Wafatnya Isa Almasih | C13: Jumat / 2 April | D13: 25719603 | E13: 25409161 | F13: 25820457 | G13: 25128781 | H13: 22751771 | I13: =(D13+E13+F13+G13)/4 -> 25519500 | J13: =((H13-I13)/I13)*100 -> -10.845545
A14: Kristen | B14: 2.Kenaikan Isa Almasih | C14: Kamis / 13 Mei | D14: 24755826 | E14: 24872874 | F14: 25198627 | G14: 24279438 | H14: 23852583 | I14: =(D14+E14+F14+G14)/4 -> 24776692 | J14: =((H14-I14)/I14)*100 -> -3.7297504
B15: 3.Natal | C15: Senin / 25 Desember | D15: 26516165 | E15: 27408592 | F15: 25976683 | G15: 26636426 | H15: 22815692 | I15: =(D15+E15+F15+G15)/4 -> 26634467 | J15: =((H15-I15)/I15)*100 -> -14.337718
A16: Hari Raya | B16: 1.Nyepi | C16: Minggu / 14 Maret | D16: 24409354 | E16: 25152062 | F16: 25952051 | G16: 27224238 | H16: 23287769 | I16: =(D16+E16+F16+G16)/4 -> 25684426 | J16: =((H16-I16)/I16)*100 -> -9.3311673
A17: Hindu / | B17: 2.Tahun Baru Imlek | C17: Jumat / 12 Februari | D17: 24822865 | E17: 24612050 | F17: 25128609 | G17: 25605729 | H17: 22254696 | I17: =(D17+E17+F17+G17)/4 -> 25042313 | J17: =((H17-I17)/I17)*100 -> -11.131629
A18: Budha/ | B18: 3.Waisak | C18: Rabu / 26 Mei | D18: 19097263 | E18: 22373731 | F18: 25978307 | G18: 25999101 | H18: 23862346 | I18: =(D18+E18+F18+G18)/4 -> 23362101 | J18: =((H18-I18)/I18)*100 -> 2.141267
A19: Tionghoa

Sheet 2022a
A1: Konsumsi Beban RSUD ULIN Hari-hari Libur Tahun 2022
A3: Kelompok | B3: Nama Hari Libur | C3: Hari | D3: Hari Ke | I3: WDMAX | J3: LDMAX | K3: TLDMAX | L3: VLDMAX
C4: Tanggal | D4: H-4 | E4: H-3 | F4: H-2 | G4: H-1 | H4: H
A5: Hari Libur | B5: 1.Tahun Baru Masehi | C5: Sabtu / 01 Januari | D5: 28045067 | E5: 27126320 | F5: 27503446 | G5: 26231291 | H5: 25726989 | I5: =(D5+E5+F5+G5)/4 -> 27226531 | J5: =((H5-I5)/I5)*100 -> -5.5076516 | K5: =('2020a'!J5+'2021a'!J5)/2 -> -5.0275885 | L5: =J5-K5 -> -0.48006314
A6: Umum | B6: 2.Proklamasi Kemerdekaan RI | C6: Rabu / 17 Agustus | D6: 26099256 | E6: 23081675 | F6: 27802201 | G6: 26751323 | H6: 23595416 | I6: =(D6+E6+F6+G6)/4 -> 25933614 | J6: =((H6-I6)/I6)*100 -> -9.0160879 | K6: =('2020a'!J6+'2021a'!J6)/2 -> -2.9218149 | L6: =J6-K6 -> -6.094273
A7: Hari Raya | B7: 1.Idul Adha | C7: Jumat / 09 Juli | D7: 27305491 | E7: 26657436 | F7: 26772536 | G7: 25895474 | H7: 23221913 | I7: =(D7+E7+F7+G7)/4 -> 26657734 | J7: =((H7-I7)/I7)*100 -> -12.888645 | K7: =('2020a'!J7+'2021a'!J7)/2 -> -2.8993084 | L7: =J7-K7 -> -9.9893364
A8: Islam | B8: 2.Tahun Baru Hijriyah | C8: Sabtu / 30 Juli | D8: 27279482 | E8: 27192133 | F8: 25449599 | G8: 25989618 | H8: 23994466 | I8: =(D8+E8+F8+G8)/4 -> 26477708 | J8: =((H8-I8)/I8)*100 -> -9.3786157 | K8: =('2020a'!J8+'2021a'!J8)/2 -> 2.1600628 | L8: =J8-K8 -> -11.538678
B9: 3.Maulid Nabi Muhammad SAW | C9: Sabtu / 08 Oktober | D9: 27869896 | E9: 28150674 | F9: 27342435 | G9: 26449761 | H9: 24348237 | I9: =(D9+E9+F9+G9)/4 -> 27453191 | J9: =((H9-I9)/I9)*100 -> -11.309993 | K9: =('2020a'!J9+'2021a'!J9)/2 -> -1.1224704 | L9: =J9-K9 -> -10.187522
B10: 4.Isra Mi'raj | C10: Senin / 28 Februari | D10: 27198992 | E10: 25907785 | F10: 23350518 | G10: 22160100 | H10: 23370764 | I10: =(D10+E10+F10+G10)/4 -> 24654349 | J10: =((H10-I10)/I10)*100 -> -5.2063215 | K10: =('2020a'!J10+'2021a'!J10)/2 -> -0.60108463 | L10: =J10-K10 -> -4.6052368
B11: 5.Idul Fitri I | C11: Senin / 02 Mei | D11: 25328500 | E11: 27064561 | F11: 23719376 | G11: 22816454 | H11: 21973445 | I11: =(D11+E11+F11+G11)/4 -> 24732223 | J11: =((H11-I11)/I11)*100 -> -11.15459 | K11: =('2020a'!J11+'2021a'!J11)/2 -> -1.2645584 | L11: =J11-K11 -> -9.8900317
B12: 6.Idul Fitri II | C12: Selasa / 03 Mei | D12: 27064561 | E12: 23719376 | F12: 22816454 | G12: 21973445 | H12: 22778254 | I12: =(D12+E12+F12+G12)/4 -> 23893459 | J12: =((H12-I12)/I12)*100 -> -4.667409 | K12: =('2020a'!J12+'2021a'!J12)/2 -> -0.99176956 | L12: =J12-K12 -> -3.6756394
A13: Hari Raya | B13: 1.Wafatnya Isa Almasih | C13: Jumat / 15 April | D13: 27745162 | E13: 27788987 | F13: 28655136 | G13: 28339705 | H13: 24624619 | I13: =(D13+E13+F13+G13)/4 -> 28132247 | J13: =((H13-I13)/I13)*100 -> -12.468353 | K13: =('2020a'!J13+'2021a'!J13)/2 -> -5.9250794 | L13: =J13-K13 -> -6.5432734
A14: Kristen | B14: 2.Kenaikan Isa Almasih | C14: Kamis / 26 Mei | D14: 23930341 | E14: 28243786 | F14: 28868950 | G14: 29910077 | H14: 24654370 | I14: =(D14+E14+F14+G14)/4 -> 27738289 | J14: =((H14-I14)/I14)*100 -> -11.117912 | K14: =('2020a'!J14+'2021a'!J14)/2 -> -4.2910148 | L14: =J14-K14 -> -6.8268972
B15: 3.Natal | C15: Minggu / 25 Desember | D15: 31059369 | E15: 30082948 | F15: 26653780 | G15: 25353530 | H15: 25043530 | I15: =(D15+E15+F15+G15)/4 -> 28287407 | J15: =((H15-I15)/I15)*100 -> -11.467566 | K15: =('2020a'!J15+'2021a'!J15)/2 -> -7.4397389 | L15: =J15-K15 -> -4.0278267
A16: Hari Raya | B16: 1.Nyepi | C16: Kamis / 03 Maret | D16: 22160100 | E16: 23370764 | F16: 27994017 | G16: 28188987 | H16: 27298992 | I16: =(D16+E16+F16+G16)/4 -> 25428467 | J16: =((H16-I16)/I16)*100 -> 7.3560291 | K16: =('2020a'!J16+'2021a'!J16)/2 -> -6.2909239 | L16: =J16-K16 -> 13.646953
A17: Hari Raya | B17: 2.Tahun Baru Imlek | C17: Selasa / 01 Februari | D17: 27935763 | E17: 26960717 | F17: 24599417 | G17: 29899691 | H17: 25825941 | I17: =(D17+E17+F17+G17)/4 -> 27348897 | J17: =((H17-I17)/I17)*100 -> -5.5686205 | K17: =('2020a'!J17+'2021a'!J17)/2 -> -15.069722 | L17: =J17-K17 -> 9.5011013
A18: Budha/ | B18: 3.Waisak | C18: Senin / 16 Mei | D18: 27872745 | E18: 26727184 | F18: 26021100 | G18: 21420104 | H18: 23610308 | I18: =(D18+E18+F18+G18)/4 -> 25510283 | J18: =((H18-I18)/I18)*100 -> -7.4478801 | K18: =('2020a'!J18+'2021a'!J18)/2 -> -0.46946095 | L18: =J18-K18 -> -6.9784191
A19: Tionghoa

Sheet 2023a
A1: Prediksi Konsumsi Beban RSUD ULIN Hari-hari Libur Tahun 2023
A3: Forecasting menggunakan Fuzzy Type 1 Inference system
A4: Kelompok | B4: Nama Hari Libur | C4: Hari | D4: Hari Ke | I4: WDMAX | J4: LDMAX | K4: TLDMAX | L4: VLDMAX | M4: Output | N4: Forecast | O4: Peramalan | P4: Aktual | Q4: Error | V4: Error
C5: Tanggal | D5: H-4 | E5: H-3 | F5: H-2 | G5: H-1 | H5: H | M5: Forecast | N5: LDMAX | O5: P'MAX(Watthours) | P5: (Watthours) | Q5: (%)
A6: Hari Libur | B6: 1.Tahun Baru Masehi | C6: Minggu / 01 Januari | D6: 24649306 | E6: 26388464 | F6: 25474318 | G6: 25889711 | H6: 21383235 | I6: =(D6+E6+F6+G6)/4 -> 25600450 | J6: =((H6-I6)/I6)*100 -> -16.473204 | K6: =('2020a'!J5+'2021a'!J5+'2022a'!J5)/3 -> -5.1876095 | L6: =J6-K6 -> -11.285594 | M6: -12 | N6: =M6+K6 -> -17.18761 | O6: =I6+((N6*I6)/100) -> 21200344 | P6: =H6 -> 21383235 | Q6: =-((O6-H6)/H6)*100 -> 0.85530116 | V6: =(O6-P6)/P6 -> -0.0085530116
A7: Umum | B7: 2.Proklamasi Kemerdekaan RI | C7: Kamis / 17 Agustus | D7: 20767780 | E7: 29123880 | F7: 29726541 | G7: 29297504 | H7: 23369011 | I7: =(D7+E7+F7+G7)/4 -> 27228926 | J7: =((H7-I7)/I7)*100 -> -14.175787 | K7: =('2020a'!J6+'2021a'!J6+'2022a'!J6)/3 -> -4.9532393 | L7: =J7-K7 -> -9.2225478 | M7: -9.7887 | N7: =M7+K7 -> -14.741939 | O7: =I7+((N7*I7)/100) -> 23214854 | P7: =H7 -> 23369011 | Q7: =-((O7-H7)/H7)*100 -> 0.65966485 | V7: =(O7-P7)/P7 -> -0.0065966485
A8: Hari Raya | B8: 1.Idul Adha | C8: Kamis / 29 Juni | D8: 22208043 | E8: 28933957 | F8: 29751614 | G8: 22312681 | H8: 20658325 | I8: =(D8+E8+F8+G8)/4 -> 25801574 | J8: =((H8-I8)/I8)*100 -> -19.933858 | K8: =('2020a'!J7+'2021a'!J7+'2022a'!J7)/3 -> -6.2290872 | L8: =J8-K8 -> -13.704771 | M8: -13.9199 | N8: =M8+K8 -> -20.148987 | O8: =I8+((N8*I8)/100) -> 20602818 | P8: =H8 -> 20658325 | Q8: =-((O8-H8)/H8)*100 -> 0.26868884 | V8: =(O8-P8)/P8 -> -0.0026868884
A9: Islam | B9: 2.Tahun Baru Hijriyah | C9: Rabu / 19 Juli | D9: 27025283 | E9: 21083588 | F9: 28915431 | G9: 29089796 | H9: 23414288 | I9: =(D9+E9+F9+G9)/4 -> 26528525 | J9: =((H9-I9)/I9)*100 -> -11.739199 | K9: =('2020a'!J8+'2021a'!J8+'2022a'!J8)/3 -> -1.6861634 | L9: =J9-K9 -> -10.053036 | M9: -7.455 | N9: =M9+K9 -> -9.1411634 | O9: =I9+((N9*I9)/100) -> 24103509 | P9: =H9 -> 23414288 | Q9: =((O9-H9)/H9)*100 -> 2.9435897 | V9: =(O9-P9)/P9 -> 0.029435897
B10: 3.Maulid Nabi Muhammad SAW | C10: Kamis / 28 September | D10: 23272362 | E10: 30686318 | F10: 29710821 | G10: 29906454 | H10: 23798221 | I10: =(D10+E10+F10+G10)/4 -> 28393989 | J10: =((H10-I10)/I10)*100 -> -16.185708 | K10: =('2020a'!J9+'2021a'!J9+'2022a'!J9)/3 -> -4.5183112 | L10: =J10-K10 -> -11.667397 | M10: -8.3453 | N10: =M10+K10 -> -12.863611 | O10: =I10+((N10*I10)/100) -> 24741496 | P10: =H10 -> 23798221 | Q10: =((O10-H10)/H10)*100 -> 3.9636401 | V10: =(O10-P10)/P10 -> 0.039636401
B11: 4.Isra Mi'raj | C11: Sabtu / 18 Februari | D11: 27210185 | E11: 27031165 | F11: 27719443 | G11: 27294019 | H11: 25703680 | I11: =(D11+E11+F11+G11)/4 -> 27313703 | J11: =((H11-I11)/I11)*100 -> -5.894563 | K11: =('2020a'!J10+'2021a'!J10+'2022a'!J10)/3 -> -2.1361636 | L11: =J11-K11 -> -3.7583995 | M11: -10.2067 | N11: =M11+K11 -> -12.342864 | O11: =I11+((N11*I11)/100) -> 23942410 | P11: =H11 -> 25703680 | Q11: =((O11-H11)/H11)*100*-1 -> 6.8522083 | V11: =(O11-P11)/P11 -> -0.068522083
B12: 5.Idul Fitri I | C12: Sabtu / 22 April | D12: 28152491 | E12: 24068160 | F12: 21402954 | G12: 19347441 | H12: 18556040 | I12: =(D12+E12+F12+G12)/4 -> 23242761 | J12: =((H12-I12)/I12)*100 -> -20.164222 | K12: =('2020a'!J11+'2021a'!J11+'2022a'!J11)/3 -> -4.5612356 | L12: =J12-K12 -> -15.602986 | M12: -14.0157 | N12: =M12+K12 -> -18.576936 | O12: =I12+((N12*I12)/100) -> 18924969 | P12: =H12 -> 18556040 | Q12: =((O12-H12)/H12)*100 -> 1.9881887 | V12: =(O12-P12)/P12 -> 0.019881887
B13: 6.Idul Fitri II | C13: Minggu / 23 April | D13: 24068160 | E13: 21402954 | F13: 19347441 | G13: 18556040 | H13: 20061148 | I13: =(D13+E13+F13+G13)/4 -> 20843649 | J13: =((H13-I13)/I13)*100 -> -3.7541463 | K13: =('2020a'!J12+'2021a'!J12+'2022a'!J12)/3 -> -2.2169827 | L13: =J13-K13 -> -1.5371636 | M13: -3 | N13: =M13+K13 -> -5.2169827 | O13: =I13+((N13*I13)/100) -> 19756239 | P13: =H13 -> 20061148 | Q13: =-((O13-H13)/H13)*100 -> 1.5198955 | V13: =(O13-P13)/P13 -> -0.015198955
A14: Hari Raya | B14: 1.Wafatnya Isa Almasih | C14: Jumat / 07 April | D14: 26929203 | E14: 26205002 | F14: 27649232 | G14: 28487018 | H14: 22518593 | I14: =(D14+E14+F14+G14)/4 -> 27317614 | J14: =((H14-I14)/I14)*100 -> -17.567498 | K14: =('2020a'!J13+'2021a'!J13+'2022a'!J13)/3 -> -8.1061705 | L14: =J14-K14 -> -9.4613273 | M14: -8.7814 | N14: =M14+K14 -> -16.887571 | O14: =I14+((N14*I14)/100) -> 22704333 | P14: =H14 -> 22518593 | Q14: =((O14-H14)/H14)*100 -> 0.8248291 | V14: =(O14-P14)/P14 -> 0.008248291
A15: Kristen | B15: 2.Kenaikan Isa Almasih | C15: Kamis / 18 Mei | D15: 23185443 | E15: 30488212 | F15: 31284871 | G15: 30880026 | H15: 25094944 | I15: =(D15+E15+F15+G15)/4 -> 28959638 | J15: =((H15-I15)/I15)*100 -> -13.345104 | K15: =('2020a'!J14+'2021a'!J14+'2022a'!J14)/3 -> -6.5666472 | L15: =J15-K15 -> -6.7784571 | M15: -7.5357 | N15: =M15+K15 -> -14.102347 | O15: =I15+((N15*I15)/100) -> 24875649 | P15: =H15 -> 25094944 | Q15: =-((O15-H15)/H15)*100 -> 0.87386048 | V15: =(O15-P15)/P15 -> -0.0087386048
B16: 3.Natal | C16: Senin / 25 Desember | D16: 33735338 | E16: 32642075 | F16: 31107022 | G16: 22935018 | H16: 23465167 | I16: =(D16+E16+F16+G16)/4 -> 30104863 | J16: =((H16-I16)/I16)*100 -> -22.055229 | K16: =('2020a'!J15+'2021a'!J15+'2022a'!J15)/3 -> -8.7823478 | L16: =J16-K16 -> -13.272881 | M16: -9.8388 | N16: =M16+K16 -> -18.621148 | O16: =I16+((N16*I16)/100) -> 24498992 | P16: =H16 -> 23465167 | Q16: =((O16-H16)/H16)*100 -> 4.4057879 | V16: =(O16-P16)/P16 -> 0.044057879
A17: Hari Raya | B17: 1.Nyepi | C17: Rabu / 22 Maret | D17: 26571839 | E17: 21378547 | F17: 28930032 | G17: 29008866 | H17: 23458006 | I17: =(D17+E17+F17+G17)/4 -> 26472321 | J17: =((H17-I17)/I17)*100 -> -11.386668 | K17: =('2020a'!J16+'2021a'!J16+'2022a'!J16)/3 -> -1.7419396 | L17: =J17-K17 -> -9.6447284 | M17: -9 | N17: =M17+K17 -> -10.74194 | O17: =I17+((N17*I17)/100) -> 23628680 | P17: =H17 -> 23458006 | Q17: =((O17-H17)/H17)*100 -> 0.72757499 | V17: =(O17-P17)/P17 -> 0.0072757499
A18: Hindu / | B18: 2.Tahun Baru Imlek | C18: Minggu / 22 Januari | D18: 27701896 | E18: 27860853 | F18: 25524164 | G18: 26210529 | H18: 20598511 | I18: =(D18+E18+F18+G18)/4 -> 26824361 | J18: =((H18-I18)/I18)*100 -> -23.209684 | K18: =('2020a'!J17+'2021a'!J17+'2022a'!J17)/3 -> -11.902688 | L18: =J18-K18 -> -11.306996 | M18: -12 | N18: =M18+K18 -> -23.902688 | O18: =I18+((N18*I18)/100) -> 20412617 | P18: =H18 -> 20598511 | Q18: =-((O18-H18)/H18)*100 -> 0.90246272 | V18: =(O18-P18)/P18 -> -0.0090246272
A19: Budha/ | B19: 3.Waisak | C19: Minggu / 04 Juni | D19: 32850749 | E19: 26168015 | F19: 25505982 | G19: 30188565 | H19: 23319886 | I19: =(D19+E19+F19+G19)/4 -> 28678328 | J19: =((H19-I19)/I19)*100 -> -18.68464 | K19: =('2020a'!J18+'2021a'!J18+'2022a'!J18)/3 -> -2.7956007 | L19: =J19-K19 -> -15.889039 | M19: -8.5731 | N19: =M19+K19 -> -11.368701 | O19: =I19+((N19*I19)/100) -> 25417975 | P19: =H19 -> 23319886 | Q19: =((O19-H19)/H19)*100 -> 8.9969958 | V19: =(O19-P19)/P19 -> 0.089969958
A20: Tionghoa | P20: MAPE | Q20: =SUM(Q6:Q19)/14 -> 2.5559063 | R20: RMSE | S20: =SQRT(SUMSQ(Q6:Q19)/COUNTA(Q6:Q19)) -> 3.6052984 | T20: R2 | U20: =RSQ(O6:O19,P6:P19) -> 0.83337866 | V20: MAE | W20: {=AVERAGE(ABS(V6:V19))} -> 0.025559063
A22: Forecasting menggunakan Interval Type 2 Fuzzy Inference system
A23: Kelompok | B23: Nama Hari Libur | C23: Hari | D23: Hari Ke | I23: WDMAX | J23: LDMAX | K23: TLDMAX | L23: VLDMAX | M23: Output | N23: Forecast | O23: Peramalan | P23: Aktual | Q23: Error
C24: Tanggal | D24: H-4 | E24: H-3 | F24: H-2 | G24: H-1 | H24: H | M24: Forecast | N24: LDMAX | O24: P'MAX(Watthours) | P24: (Watthours) | Q24: (%)
A25: Hari Libur | B25: 1.Tahun Baru Masehi | C25: Minggu / 01 Januari | D25: 24649306 | E25: 26388464 | F25: 25474318 | G25: 25889711 | H25: 21383235 | I25: 25600450 | J25: -16.473204 | K25: -5.1876095 | L25: -11.285594 | M25: -12 | N25: =M25+K25 -> -17.18761 | O25: =I25+((N25*I25)/100) -> 21200344 | P25: =H25 -> 21383235 | Q25: =-((O25-H25)/H25)*100 -> 0.85530116 | V25: =(O25-P25)/P25 -> -0.0085530116
A26: Umum | B26: 2.Proklamasi Kemerdekaan RI | C26: Kamis / 17 Agustus | D26: 20767780 | E26: 29123880 | F26: 29726541 | G26: 29297504 | H26: 23369011 | I26: 27228926 | J26: -14.175787 | K26: -4.9532393 | L26: -9.2225478 | M26: -10.2628 | N26: =M26+K26 -> -15.216039 | O26: =I26+((N26*I26)/100) -> 23085762 | P26: =H26 -> 23369011 | Q26: =-((O26-H26)/H26)*100 -> 1.2120731 | V26: =(O26-P26)/P26 -> -0.012120731
A27: Hari Raya | B27: 1.Idul Adha | C27: Kamis / 29 Juni | D27: 22208043 | E27: 28933957 | F27: 29751614 | G27: 22312681 | H27: 20658325 | I27: 25801574 | J27: -19.933858 | K27: -6.2290872 | L27: -13.704771 | M27: -13.9347 | N27: =M27+K27 -> -20.163787 | O27: =I27+((N27*I27)/100) -> 20598999 | P27: =H27 -> 20658325 | Q27: =-((O27-H27)/H27)*100 -> 0.28717355 | V27: =(O27-P27)/P27 -> -0.0028717355
A28: Islam | B28: 2.Tahun Baru Hijriyah | C28: Rabu / 19 Juli | D28: 27025283 | E28: 21083588 | F28: 28915431 | G28: 29089796 | H28: 23414288 | I28: 26528525 | J28: -11.739199 | K28: -1.6861634 | L28: -10.053036 | M28: -7.4137 | N28: =M28+K28 -> -9.0998634 | O28: =I28+((N28*I28)/100) -> 24114465 | P28: =H28 -> 23414288 | Q28: =((O28-H28)/H28)*100 -> 2.9903828 | V28: =(O28-P28)/P28 -> 0.029903828
B29: 3.Maulid Nabi Muhammad SAW | C29: Kamis / 28 September | D29: 23272362 | E29: 30686318 | F29: 29710821 | G29: 29906454 | H29: 23798221 | I29: 28393989 | J29: -16.185708 | K29: -4.5183112 | L29: -11.667397 | M29: -9.0346 | N29: =M29+K29 -> -13.552911 | O29: =I29+((N29*I29)/100) -> 24545777 | P29: =H29 -> 23798221 | Q29: =((O29-H29)/H29)*100 -> 3.1412267 | V29: =(O29-P29)/P29 -> 0.031412267
B30: 4.Isra Mi'raj | C30: Sabtu / 18 Februari | D30: 27210185 | E30: 27031165 | F30: 27719443 | G30: 27294019 | H30: 25703680 | I30: 27313703 | J30: -5.894563 | K30: -2.1361636 | L30: -3.7583995 | M30: -10.3849 | N30: =M30+K30 -> -12.521064 | O30: =I30+((N30*I30)/100) -> 23893737 | P30: =H30 -> 25703680 | Q30: =-((O30-H30)/H30)*100 -> 7.0415703 | V30: =(O30-P30)/P30 -> -0.070415703
B31: 5.Idul Fitri I | C31: Sabtu / 22 April | D31: 28152491 | E31: 24068160 | F31: 21402954 | G31: 19347441 | H31: 18556040 | I31: 23242761 | J31: -20.164222 | K31: -4.5612356 | L31: -15.602986 | M31: -14.204 | N31: =M31+K31 -> -18.765236 | O31: =I31+((N31*I31)/100) -> 18881203 | P31: =H31 -> 18556040 | Q31: =((O31-H31)/H31)*100 -> 1.7523295 | V31: =(O31-P31)/P31 -> 0.017523295
B32: 6.Idul Fitri II | C32: Minggu / 23 April | D32: 24068160 | E32: 21402954 | F32: 19347441 | G32: 18556040 | H32: 20061148 | I32: 20843649 | J32: -3.7541463 | K32: -2.2169827 | L32: -1.5371636 | M32: -3 | N32: =M32+K32 -> -5.2169827 | O32: =I32+((N32*I32)/100) -> 19756239 | P32: =H32 -> 20061148 | Q32: =-((O32-H32)/H32)*100 -> 1.5198955 | V32: =(O32-P32)/P32 -> -0.015198955
A33: Hari Raya | B33: 1.Wafatnya Isa Almasih | C33: Jumat / 07 April | D33: 26929203 | E33: 26205002 | F33: 27649232 | G33: 28487018 | H33: 22518593 | I33: 27317614 | J33: -17.567498 | K33: -8.1061705 | L33: -9.4613273 | M33: -8.8745 | N33: =M33+K33 -> -16.980671 | O33: =I33+((N33*I33)/100) -> 22678900 | P33: =H33 -> 22518593 | Q33: =((O33-H33)/H33)*100 -> 0.71188822 | V33: =(O33-P33)/P33 -> 0.0071188822
A34: Kristen | B34: 2.Kenaikan Isa Almasih | C34: Kamis / 18 Mei | D34: 23185443 | E34: 30488212 | F34: 31284871 | G34: 30880026 | H34: 25094944 | I34: 28959638 | J34: -13.345104 | K34: -6.5666472 | L34: -6.7784571 | M34: -7.0828 | N34: =M34+K34 -> -13.649447 | O34: =I34+((N34*I34)/100) -> 25006808 | P34: =H34 -> 25094944 | Q34: =-((O34-H34)/H34)*100 -> 0.35121258 | V34: =(O34-P34)/P34 -> -0.0035121258
B35: 3.Natal | C35: Senin / 25 Desember | D35: 33735338 | E35: 32642075 | F35: 31107022 | G35: 22935018 | H35: 23465167 | I35: 30104863 | J35: -22.055229 | K35: -8.7823478 | L35: -13.272881 | M35: -10.4534 | N35: =M35+K35 -> -19.235748 | O35: =I35+((N35*I35)/100) -> 24313968 | P35: =H35 -> 23465167 | Q35: =((O35-H35)/H35)*100 -> 3.6172809 | V35: =(O35-P35)/P35 -> 0.036172809
A36: Hari Raya | B36: 1.Nyepi | C36: Rabu / 22 Maret | D36: 26571839 | E36: 21378547 | F36: 28930032 | G36: 29008866 | H36: 23458006 | I36: 26472321 | J36: -11.386668 | K36: -1.7419396 | L36: -9.6447284 | M36: -9 | N36: =M36+K36 -> -10.74194 | O36: =I36+((N36*I36)/100) -> 23628680 | P36: =H36 -> 23458006 | Q36: =((O36-H36)/H36)*100 -> 0.72757499 | V36: =(O36-P36)/P36 -> 0.0072757499
A37: Hindu / | B37: 2.Tahun Baru Imlek | C37: Minggu / 22 Januari | D37: 27701896 | E37: 27860853 | F37: 25524164 | G37: 26210529 | H37: 20598511 | I37: 26824361 | J37: -23.209684 | K37: -11.902688 | L37: -11.306996 | M37: -12 | N37: =M37+K37 -> -23.902688 | O37: =I37+((N37*I37)/100) -> 20412617 | P37: =H37 -> 20598511 | Q37: =-((O37-H37)/H37)*100 -> 0.90246272 | V37: =(O37-P37)/P37 -> -0.0090246272
A38: Budha/ | B38: 3.Waisak | C38: Minggu / 04 Juni | D38: 32850749 | E38: 26168015 | F38: 25505982 | G38: 30188565 | H38: 23319886 | I38: 28678328 | J38: -18.68464 | K38: -2.7956007 | L38: -15.889039 | M38: -9.3435 | N38: =M38+K38 -> -12.139101 | O38: =I38+((N38*I38)/100) -> 25197037 | P38: =H38 -> 23319886 | Q38: =((O38-H38)/H38)*100 -> 8.0495733 | V38: =(O38-P38)/P38 -> 0.080495733
A39: Tionghoa | P39: MAPE | Q39: =SUM(Q25:Q38)/14 -> 2.3685675 | R39: RMSE | S39: =SQRT(SUMSQ(Q25:Q38)/COUNTA(Q25:Q38)) -> 3.3371456 | T39: R2 | U39: =RSQ(O25:O38,P25:P38) -> 0.84879168 | V39: MAE | W39: {=AVERAGE(ABS(V25:V38))} -> 0.023685675
A41: Forecasting menggunakan Fuzzytype2-CSA
A42: Kelompok | B42: Nama Hari Libur | C42: Hari | D42: Hari Ke | I42: WDMAX | J42: LDMAX | K42: TLDMAX | L42: VLDMAX | M42: Output | N42: Forecast | O42: Peramalan | P42: Aktual | Q42: Error
C43: Tanggal | D43: H-4 | E43: H-3 | F43: H-2 | G43: H-1 | H43: H | M43: Forecast | N43: LDMAX | O43: P'MAX(Watthours) | P43: (Watthours) | Q43: (%)
...

Sheet hasil VLD 2023
B1: HASIL FORCASTING VLD TAHUN 2023
B3: Type-1 | E3: IT2-FIS | H3: IT2FIS-CSA | K3: IT2FIS-FA | N3: IT2FIS-ZOA | Q3: IT2FIS-OOA
B4: Actual | C4: Forecast | D4: Error | E4: Actual | F4: Forecast | G4: Error | H4: Actual | I4: Forecast | J4: Error | K4: Actual | L4: Forecast | M4: Error | N4: Actual | O4: Forecast | P4: Error | Q4: Actual | R4: Forecast | S4: Error
B5: -11.285594 | C5: -12 | D5: 0.85530116 | E5: -11.285594 | F5: -12 | G5: 0.85530116 | H5: -11.285594 | I5: -11.9628 | J5: 0.81076456 | K5: -11.285594 | L5: -11.9595 | M5: 0.80681373 | N5: -11.285594 | O5: -11.9837 | P5: 0.83578647 | Q5: -11.285594 | R5: -11.9883 | S5: 0.84129368
B6: -9.2225478 | C6: -9.7887 | D6: 0.65966485 | E6: -9.2225478 | F6: -10.2628 | G6: 1.2120731 | H6: -9.2225478 | I6: -10.2758 | J6: 1.2272203 | K6: -9.2225478 | L6: -10.3246 | M6: 1.2840807 | N6: -9.2225478 | O6: -10.2675 | P6: 1.2175494 | Q6: -9.2225478 | R6: -10.3191 | S6: 1.2776723
B7: -13.704771 | C7: -13.9199 | D7: 0.26868884 | E7: -13.704771 | F7: -13.9347 | G7: 0.28717355 | H7: -13.704771 | I7: -13.65 | J7: 0.068407463 | K7: -13.704771 | L7: -13.65 | M7: 0.068407463 | N7: -13.704771 | O7: -13.65 | P7: 0.068407463 | Q7: -13.704771 | R7: -13.65 | S7: 0.068407463
B8: -10.053036 | C8: -7.455 | D8: 2.9435897 | E8: -10.053036 | F8: -7.4137 | G8: 2.9903828 | H8: -10.053036 | I8: -7.8533 | J8: 2.4923134 | K8: -10.053036 | L8: -7.8514 | M8: 2.4944662 | N8: -10.053036 | O8: -7.8533 | P8: 2.4923134 | Q8: -10.053036 | R8: -7.8529 | S8: 2.4927666
B9: -11.667397 | C9: -8.3453 | D9: 3.9636401 | E9: -11.667397 | F9: -9.0346 | G9: 3.1412267 | H9: -11.667397 | I9: -9.2979 | J9: 2.8270798 | K9: -11.667397 | L9: -9.2942 | M9: 2.8314943 | N9: -11.667397 | O9: -9.3543 | P9: 2.7597882 | Q9: -11.667397 | R9: -9.3459 | S9: 2.7698103
B10: -3.7583995 | C10: -10.2067 | D10: 6.8522083 | E10: -3.7583995 | F10: -10.3849 | G10: 7.0415703 | H10: -3.7583995 | I10: -9.15 | J10: 5.7293188 | K10: -3.7583995 | L10: -9.15 | M10: 5.7293188 | N10: -3.7583995 | O10: -9.15 | P10: 5.7293188 | Q10: -3.7583995 | R10: -9.15 | S10: 5.7293188
B11: -15.602986 | C11: -14.0157 | D11: 1.9881887 | E11: -15.602986 | F11: -14.204 | G11: 1.7523295 | H11: -15.602986 | I11: -14.2387 | J11: 1.7088653 | K11: -15.602986 | L11: -14.1996 | M11: 1.7578409 | N11: -15.602986 | O11: -14.2413 | P11: 1.7056086 | Q11: -15.602986 | R11: -14.2136 | S11: 1.7403049
B12: -1.5371636 | C12: -3 | D12: 1.5198955 | E12: -1.5371636 | F12: -3 | G12: 1.5198955 | H12: -1.5371636 | I12: -2.9333 | J12: 1.4505938 | K12: -1.5371636 | L12: -2.921 | M12: 1.437814 | N12: -1.5371636 | O12: -2.9608 | P12: 1.4791664 | Q12: -1.5371636 | R12: -2.8949 | S12: 1.4106959
B13: -9.4613273 | C13: -8.7814 | D13: 0.8248291 | E13: -9.4613273 | F13: -8.8745 | G13: 0.71188822 | H13: -9.4613273 | I13: -8.9576 | J13: 0.61107846 | K13: -9.4613273 | L13: -8.9465 | M13: 0.62454403 | N13: -9.4613273 | O13: -8.9597 | P13: 0.60853093 | Q13: -9.4613273 | R13: -8.9578 | S13: 0.61083584
B14: -6.7784571 | C14: -7.5357 | D14: 0.87386048 | E14: -6.7784571 | F14: -7.0828 | G14: 0.35121258 | H14: -6.7784571 | I14: -6.9804 | J14: 0.23304268 | K14: -6.7784571 | L14: -6.9466 | M14: 0.19403738 | N14: -6.7784571 | O14: -6.9623 | P14: 0.21215523 | Q14: -6.7784571 | R14: -6.9364 | S14: 0.18226655
B15: -13.272881 | C15: -9.8388 | D15: 4.4057879 | E15: -13.272881 | F15: -10.4534 | G15: 3.6172809 | H15: -13.272881 | I15: -10.521 | J15: 3.5305528 | K15: -13.272881 | L15: -10.5568 | M15: 3.4846229 | N15: -13.272881 | O15: -10.5917 | P15: 3.4398476 | Q15: -13.272881 | R15: -10.5825 | S15: 3.4516508
B16: -9.6447284 | C16: -9 | D16: 0.72757499 | E16: -9.6447284 | F16: -9 | G16: 0.72757499 | H16: -9.6447284 | I16: -9.0707 | J16: 0.64779015 | K16: -9.6447284 | L16: -9.0451 | M16: 0.67667971 | N16: -9.6447284 | O16: -9.0708 | P16: 0.6476773 | Q16: -9.6447284 | R16: -9.0696 | S16: 0.6490315
... B18: -15.889039 | C18: -8.5731 | D18: 8.9969958 | E18: -15.889039 | F18: -9.3435 | G18: 8.0495733 | H18: -15.889039 | I18: -9.4201 | J18: 7.9553721 | K18: -15.889039 | L18: -9.4863 | M18: 7.8739607 | N18: -15.889039 | O18: -9.4122 | P18: 7.9650874 | Q18: -15.889039 | R18: -9.4721 | S18: 7.8914236
B19: MAPE | D19: 2.5559063 | E19: MAPE | G19: 2.3685675 | H19: MAPE | J19: 2.1533435 | K19: MAPE | M19: 2.1510696 | N19: MAPE | P19: 2.1459561 | Q19: MAPE | S19: 2.1430131
B20: RMSE | D20: 3.6052984 | E20: RMSE | G20: 3.3371456 | H20: RMSE | K20: RMSE | N20: RMSE | Q20: RMSE
B21: MAE | D21: 0.025559063 | E21: MAE | G21: 0.023685675 | H21: MAE | K21: MAE | N21: MAE | Q21: MAE
B22: R2 | D22: 0.83337866 | E22: R2 | H22: R2 | K22: R2 | N22: R2 | Q22: R2

Sheet 2024a
A1: Prediksi Konsumsi Beban RSUD ULIN Hari-hari Libur Tahun 2024
A3: Forecasting menggunakan Fuzzy Type 1 Inference system
A4: Kelompok | B4: Nama Hari Libur | C4: Hari | D4: Hari Ke | I4: WDMAX | J4: LDMAX | K4: TLDMAX | L4: VLDMAX | M4: Output | N4: Forecast | O4: Peramalan | P4: Aktual | Q4: Error | V4: Error
C5: Tanggal | D5: H-4 | E5: H-3 | F5: H-2 | G5: H-1 | H5: H | M5: Forecast | N5: LDMAX | O5: P'MAX(Watthours) | P5: (Watthours) | Q5: (%)
A6: Hari Libur | B6: 1.Tahun Baru Masehi | C6: Senin / 01 Januari | D6: 31962075 | E6: 31389832 | F6: 30887111 | G6: 27674659 | H6: 25001165 | I6: =(D6+E6+F6+G6)/4 -> 30478419 | J6: =((H6-I6)/I6)*100 -> -17.970926 | K6: =('2020a'!J5+'2021a'!J5+'2022a'!J5+'2023a'!J6)/4 -> -8.0090081 | L6: =J6-K6 -> -9.9619177 | M6: -6.8007 | N6: =M6+K6 -> -14.809708 | O6: =I6+((N6*I6)/100) -> 25964654 | P6: =H6 -> 25001165 | Q6: =((O6-H6)/H6)*100 -> 3.8537772 | V6: =(O6-P6)/P6 -> 0.038537772
A7: Umum | B7: 2.Proklamasi Kemerdekaan RI | C7: Sabtu / 17 Agustus | D7: 27235140 | E7: 28261723 | F7: 29261318 | G7: 25243722 | H7: 24512818 | I7: =(D7+E7+F7+G7)/4 -> 27500476 | J7: =((H7-I7)/I7)*100 -> -10.864023 | K7: =('2020a'!J6+'2021a'!J6+'2022a'!J6+'2023a'!J7)/4 -> -7.2588762 | L7: =J7-K7 -> -3.6051464 | M7: -3 | N7: =M7+K7 -> -10.258876 | O7: =I7+((N7*I7)/100) -> 24679236 | P7: =H7 -> 24512818 | Q7: =((O7-H7)/H7)*100 -> 0.67890256 | V7: =(O7-P7)/P7 -> 0.0067890256
A8: Hari Raya | B8: 1.Idul Adha | C8: Senin / 17 Juni | D8: 31957263 | E8: 31021032 | F8: 30016114 | G8: 25024126 | H8: 24126175 | I8: =(D8+E8+F8+G8)/4 -> 29504634 | J8: =((H8-I8)/I8)*100 -> -18.229199 | K8: =('2020a'!J7+'2021a'!J7+'2022a'!J7+'2023a'!J8)/4 -> -9.65528 | L8: =J8-K8 -> -8.5739194 | M8: -9 | N8: =M8+K8 -> -18.65528 | O8: =I8+((N8*I8)/100) -> 24000462 | P8: =H8 -> 24126175 | Q8: =-((O8-H8)/H8)*100 -> 0.52106689 | V8: =(O8-P8)/P8 -> -0.0052106689
A9: Islam | B9: 2.Tahun Baru Hijriyah | C9: Minggu / 07 Juli | D9: 30050153 | E9: 26598716 | F9: 26845796 | G9: 27003129 | H9: 25429719 | I9: =(D9+E9+F9+G9)/4 -> 27624448 | J9: =((H9-I9)/I9)*100 -> -7.9448821 | K9: =('2020a'!J8+'2021a'!J8+'2022a'!J8+'2023a'!J9)/4 -> -4.1994223 | L9: =J9-K9 -> -3.7454598 | M9: -3 | N9: =M9+K9 -> -7.1994223 | O9: =I9+((N9*I9)/100) -> 25635648 | P9: =H9 -> 25429719 | Q9: =((O9-H9)/H9)*100 -> 0.8097972 | V9: =(O9-P9)/P9 -> 0.008097972
B10: 3.Maulid Nabi Muhammad SAW | C10: Senin / 16 September | D10: 30101526 | E10: 28313129 | F10: 28015138 | G10: 24826248 | H10: 24516279 | I10: =(D10+E10+F10+G10)/4 -> 27814010 | J10: =((H10-I10)/I10)*100 -> -11.856368 | K10: =('2020a'!J9+'2021a'!J9+'2022a'!J9+'2023a'!J10)/4 -> -7.4351604 | L10: =J10-K10 -> -4.421208 | M10: -6.4094 | N10: =M10+K10 -> -13.84456 | O10: =I10+((N10*I10)/100) -> 23963283 | P10: =H10 -> 24516279 | Q10: =-((O10-H10)/H10)*100 -> 2.2556275 | V10: =(O10-P10)/P10 -> -0.022556275
B11: 4.Isra Mi'raj | C11: Kamis / 08 Februari | D11: 22303983 | E11: 29489179 | F11: 31781409 | G11: 29018457 | H11: 23904977 | I11: =(D11+E11+F11+G11)/4 -> 28148257 | J11: =((H11-I11)/I11)*100 -> -15.074752 | K11: =('2020a'!J10+'2021a'!J10+'2022a'!J10+'2023a'!J11)/4 -> -3.0757634 | L11: =J11-K11 -> -11.998988 | M11: -12 | N11: =M11+K11 -> -15.075763 | O11: =I11+((N11*I11)/100) -> 23904692 | P11: =H11 -> 23904977 | Q11: =((O11-H11)/H11)*100*-1 -> 0.0011914375 | V11: =(O11-P11)/P11 -> -1.1914375e-05
B12: 5.Idul Fitri I | C12: Sabtu / 10 April | D12: 28929860 | E12: 23254492 | F12: 25535228 | G12: 22107167 | H12: 20221836 | I12: =(D12+E12+F12+G12)/4 -> 24956687 | J12: =((H12-I12)/I12)*100 -> -18.972272 | K12: =('2020a'!J11+'2021a'!J11+'2022a'!J11+'2023a'!J12)/4 -> -8.4619821 | L12: =J12-K12 -> -10.51029 | M12: -12 | N12: =M12+K12 -> -20.461982 | O12: =I12+((N12*I12)/100) -> 19850054 | P12: =H12 -> 20221836 | Q12: =-((O12-H12)/H12)*100 -> 1.8385187 | V12: =(O12-P12)/P12 -> -0.018385187
B13: 6.Idul Fitri II | C13: Minggu / 11 April | D13: 23254492 | E13: 25535228 | F13: 22107167 | G13: 20221836 | H13: 20717923 | I13: =(D13+E13+F13+G13)/4 -> 22779681 | J13: =((H13-I13)/I13)*100 -> -9.0508644 | K13: =('2020a'!J12+'2021a'!J12+'2022a'!J12+'2023a'!J13)/4 -> -2.6012736 | L13: =J13-K13 -> -6.4495908 | M13: -6 | N13: =M13+K13 -> -8.6012736 | O13: =I13+((N13*I13)/100) -> 20820338 | P13: =H13 -> 20717923 | Q13: =((O13-H13)/H13)*100 -> 0.49433214 | V13: =(O13-P13)/P13 -> 0.0049433214
A14: Hari Raya | B14: 1.Wafatnya Isa Almasih | C14: Jumat / 29 Maret | D14: 33264637 | E14: 31685394 | F14: 32736843 | G14: 31201640 | H14: 25986092 | I14: =(D14+E14+F14+G14)/4 -> 32222128 | J14: =((H14-I14)/I14)*100 -> -19.353274 | K14: =('2020a'!J13+'2021a'!J13+'2022a'!J13+'2023a'!J14)/4 -> -10.471502 | L14: =J14-K14 -> -8.8817713 | M14: -9.426 | N14: =M14+K14 -> -19.897502 | O14: =I14+((N14*I14)/100) -> 25810730 | P14: =H14 -> 25986092 | Q14: =-((O14-H14)/H14)*100 -> 0.67483048 | V14: =(O14-P14)/P14 -> -0.0067483048
A15: Kristen | B15: 2.Kenaikan Isa Almasih | C15: Kamis / 09 Mei | D15: 28258348 | E15: 30515259 | F15: 30187192 | G15: 28987478 | H15: 26009815 | I15: =(D15+E15+F15+G15)/4 -> 29487069 | J15: =((H15-I15)/I15)*100 -> -11.792473 | K15: =('2020a'!J14+'2021a'!J14+'2022a'!J14+'2023a'!J15)/4 -> -8.2612614 | L15: =J15-K15 -> -3.5312117 | M15: -3 | N15: =M15+K15 -> -11.261261 | O15: =I15+((N15*I15)/100) -> 26166453 | P15: =H15 -> 26009815 | Q15: =((O15-H15)/H15)*100 -> 0.60222942 | V15: =(O15-P15)/P15 -> 0.0060222942
B16: 3.Natal | C16: Senin / 25 Desember | D16: 32988766 | E16: 31713502 | F16: 30089571 | G16: 23894817 | H16: 24792649 | I16: =(D16+E16+F16+G16)/4 -> 29671664 | J16: =((H16-I16)/I16)*100 -> -16.443348 | K16: =('2020a'!J15+'2021a'!J15+'2022a'!J15+'2023a'!J16)/4 -> -12.100568 | L16: =J16-K16 -> -4.3427803 | M16: -6 | N16: =M16+K16 -> -18.100568 | O16: =I16+((N16*I16)/100) -> 24300924 | P16: =H16 -> 24792649 | Q16: =-((O16-H16)/H16)*100 -> 1.9833486 | V16: =(O16-P16)/P16 -> -0.019833486
A17: Hari Raya | B17: 1.Nyepi | C17: Senin / 11 Maret | D17: 32770228 | E17: 30045391 | F17: 28826716 | G17: 22574331 | H17: 23546634 | I17: =(D17+E17+F17+G17)/4 -> 28554167 | J17: =((H17-I17)/I17)*100 -> -17.536958 | K17: =('2020a'!J16+'2021a'!J16+'2022a'!J16+'2023a'!J17)/4 -> -4.1531217 | L17: =J17-K17 -> -13.383836 | M17: -9.0389 | N17: =M17+K17 -> -13.192022 | O17: =I17+((N17*I17)/100) -> 24787295 | P17: =H17 -> 23546634 | Q17: =((O17-H17)/H17)*100 -> 5.2689492 | V17: =(O17-P17)/P17 -> 0.052689492
A18: Hindu / | B18: 2.Tahun Baru Imlek | C18: Sabtu / 10 Pebruari | D18: 31781409 | E18: 29018457 | F18: 23904977 | G18: 24557871 | H18: 22710129 | I18: =(D18+E18+F18+G18)/4 -> 27315679 | J18: =((H18-I18)/I18)*100 -> -16.860463 | K18: =('2020a'!J17+'2021a'!J17+'2022a'!J17+'2023a'!J18)/4 -> -14.729437 | L18: =J18-K18 -> -2.1310256 | M18: -3 | N18: =M18+K18 -> -17.729437 | O18: =I18+((N18*I18)/100) -> 22472763 | P18: =H18 -> 22710129 | Q18: =-((O18-H18)/H18)*100 -> 1.0451999 | V18: =(O18-P18)/P18 -> -0.010451999
A19: Budha/ | B19: 3.Waisak | C19: Kamis / 23 Mei | D19: 23174758 | E19: 30251429 | F19: 29853482 | G19: 29008794 | H19: 25031136 | I19: =(D19+E19+F19+G19)/4 -> 28072116 | J19: =((H19-I19)/I19)*100 -> -10.832742 | K19: =('2020a'!J18+'2021a'!J18+'2022a'!J18+'2023a'!J19)/4 -> -6.7678605 | L19: =J19-K19 -> -4.0648817 | M19: -3 | N19: =M19+K19 -> -9.7678605 | O19: =I19+((N19*I19)/100) -> 25330071 | P19: =H19 -> 25031136 | Q19: =((O19-H19)/H19)*100 -> 1.1942519 | V19: =(O19-P19)/P19 -> 0.011942519
A20: Tionghoa | P20: MAPE | Q20: =SUM(Q6:Q19)/14 -> 1.5158588 | R20: RMSE | S20: =SQRT(SUMSQ(Q6:Q19)/COUNTA(Q6:Q19)) -> 2.0699278 | T20: R2 | U20: =RSQ(O6:O19,P6:P19) -> 0.93010072 | V20: MAE | W20: {=AVERAGE(ABS(V6:V19))} -> 0.015158588
A22: Forecasting menggunakan Interval Type 2 Fuzzy Inference system
A23: Kelompok | B23: Nama Hari Libur | C23: Hari | D23: Hari Ke | I23: WDMAX | J23: LDMAX | K23: TLDMAX | L23: VLDMAX | M23: Output | N23: Forecast | O23: Peramalan | P23: Aktual | Q23: Error
C24: Tanggal | D24: H-4 | E24: H-3 | F24: H-2 | G24: H-1 | H24: H | M24: Forecast | N24: LDMAX | O24: P'MAX(Watthours) | P24: (Watthours) | Q24: (%)
A25: Hari Libur | B25: 1.Tahun Baru Masehi | C25: Senin / 01 Januari | D25: 31962075 | E25: 31389832 | F25: 30887111 | G25: 27674659 | H25: 25001165 | I25: 30478419 | J25: -17.970926 | K25: -8.0090081 | L25: -9.9619177 | M25: -6.4974 | N25: =M25+K25 -> -14.506408 | O25: =I25+((N25*I25)/100) -> 26057095 | P25: =H25 -> 25001165 | Q25: =((O25-H25)/H25)*100 -> 4.2235241 | V25: =(O25-P25)/P25 -> 0.042235241
A26: Umum | B26: 2.Proklamasi Kemerdekaan RI | C26: Sabtu / 17 Agustus | D26: 27235140 | E26: 28261723 | F26: 29261318 | G26: 25243722 | H26: 24512818 | I26: 27500476 | J26: -10.864023 | K26: -7.2588762 | L26: -3.6051464 | M26: -3 | N26: =M26+K26 -> -10.258876 | O26: =I26+((N26*I26)/100) -> 24679236 | P26: =H26 -> 24512818 | Q26: =((O26-H26)/H26)*100 -> 0.67890256 | V26: =(O26-P26)/P26 -> 0.0067890256
A27: Hari Raya | B27: 1.Idul Adha | C27: Senin / 17 Juni | D27: 31957263 | E27: 31021032 | F27: 30016114 | G27: 25024126 | H27: 24126175 | I27: 29504634 | J27: -18.229199 | K27: -9.65528 | L27: -8.5739194 | M27: -9 | N27: =M27+K27 -> -18.65528 | O27: =I27+((N27*I27)/100) -> 24000462 | P27: =H27 -> 24126175 | Q27: =-((O27-H27)/H27)*100 -> 0.52106689 | V27: =(O27-P27)/P27 -> -0.0052106689
A28: Islam | B28: 2.Tahun Baru Hijriyah | C28: Minggu / 07 Juli | D28: 30050153 | E28: 26598716 | F28: 26845796 | G28: 27003129 | H28: 25429719 | I28: 27624448 | J28: -7.9448821 | K28: -4.1994223 | L28: -3.7454598 | M28: -3 | N28: =M28+K28 -> -7.1994223 | O28: =I28+((N28*I28)/100) -> 25635648 | P28: =H28 -> 25429719 | Q28: =((O28-H28)/H28)*100 -> 0.8097972 | V28: =(O28-P28)/P28 -> 0.008097972
B29: 3.Maulid Nabi Muhammad SAW | C29: Senin / 16 September | D29: 30101526 | E29: 28313129 | F29: 28015138 | G29: 24826248 | H29: 24516279 | I29: 27814010 | J29: -11.856368 | K29: -7.4351604 | L29: -4.421208 | M29: -6.2593 | N29: =M29+K29 -> -13.69446 | O29: =I29+((N29*I29)/100) -> 24005032 | P29: =H29 -> 24516279 | Q29: =-((O29-H29)/H29)*100 -> 2.0853373 | V29: =(O29-P29)/P29 -> -0.020853373
B30: 4.Isra Mi'raj | C30: Kamis / 08 Februari | D30: 22303983 | E30: 29489179 | F30: 31781409 | G30: 29018457 | H30: 23904977 | I30: 28148257 | J30: -15.074752 | K30: -3.0757634 | L30: -11.998988 | M30: -12 | N30: =M30+K30 -> -15.075763 | O30: =I30+((N30*I30)/100) -> 23904692 | P30: =H30 -> 23904977 | Q30: =((O30-H30)/H30)*100*-1 -> 0.0011914375 | V30: =(O30-P30)/P30 -> -1.1914375e-05
B31: 5.Idul Fitri I | C31: Sabtu / 10 April | D31: 28929860 | E31: 23254492 | F31: 25535228 | G31: 22107167 | H31: 20221836 | I31: 24956687 | J31: -18.972272 | K31: -8.4619821 | L31: -10.51029 | M31: -12 | N31: =M31+K31 -> -20.461982 | O31: =I31+((N31*I31)/100) -> 19850054 | P31: =H31 -> 20221836 | Q31: =-((O31-H31)/H31)*100 -> 1.8385187 | V31: =(O31-P31)/P31 -> -0.018385187
B32: 6.Idul Fitri II | C32: Minggu / 11 April | D32: 23254492 | E32: 25535228 | F32: 22107167 | G32: 20221836 | H32: 20717923 | I32: 22779681 | J32: -9.0508644 | K32: -2.6012736 | L32: -6.4495908 | M32: -6 | N32: =M32+K32 -> -8.6012736 | O32: =I32+((N32*I32)/100) -> 20820338 | P32: =H32 -> 20717923 | Q32: =((O32-H32)/H32)*100 -> 0.49433214 | V32: =(O32-P32)/P32 -> 0.0049433214
A33: Hari Raya | B33: 1.Wafatnya Isa Almasih | C33: Jumat / 29 Maret | D33: 33264637 | E33: 31685394 | F33: 32736843 | G33: 31201640 | H33: 25986092 | I33: 32222128 | J33: -19.353274 | K33: -10.471502 | L33: -8.8817713 | M33: -9.8281 | N33: =M33+K33 -> -20.299602 | O33: =I33+((N33*I33)/100) -> 25681164 | P33: =H33 -> 25986092 | Q33: =-((O33-H33)/H33)*100 -> 1.1734248 | V33: =(O33-P33)/P33 -> -0.011734248
A34: Kristen | B34: 2.Kenaikan Isa Almasih | C34: Kamis / 09 Mei | D34: 28258348 | E34: 30515259 | F34: 30187192 | G34: 28987478 | H34: 26009815 | I34: 29487069 | J34: -11.792473 | K34: -8.2612614 | L34: -3.5312117 | M34: -3 | N34: =M34+K34 -> -11.261261 | O34: =I34+((N34*I34)/100) -> 26166453 | P34: =H34 -> 26009815 | Q34: =((O34-H34)/H34)*100 -> 0.60222942 | V34: =(O34-P34)/P34 -> 0.0060222942
B35: 3.Natal | C35: Senin / 25 Desember | D35: 32988766 | E35: 31713502 | F35: 30089571 | G35: 23894817 | H35: 24792649 | I35: 29671664 | J35: -16.443348 | K35: -12.100568 | L35: -4.3427803 | M35: -6 | N35: =M35+K35 -> -18.100568 | O35: =I35+((N35*I35)/100) -> 24300924 | P35: =H35 -> 24792649 | Q35: =-((O35-H35)/H35)*100 -> 1.9833486 | V35: =(O35-P35)/P35 -> -0.019833486
A36: Hari Raya | B36: 1.Nyepi | C36: Senin / 11 Maret | D36: 32770228 | E36: 30045391 | F36: 28826716 | G36: 22574331 | H36: 23546634 | I36: 28554167 | J36: -17.536958 | K36: -4.1531217 | L36: -13.383836 | M36: -9.5267 | N36: =M36+K36 -> -13.679822 | O36: =I36+((N36*I36)/100) -> 24648007 | P36: =H36 -> 23546634 | Q36: =((O36-H36)/H36)*100 -> 4.6774115 | V36: =(O36-P36)/P36 -> 0.046774115
A37: Hindu / | B37: 2.Tahun Baru Imlek | C37: Sabtu / 10 Pebruari | D37: 31781409 | E37: 29018457 | F37: 23904977 | G37: 24557871 | H37: 22710129 | I37: 27315679 | J37: -16.860463 | K37: -14.729437 | L37: -2.1310256 | M37: -3 | N37: =M37+K37 -> -17.729437 | O37: =I37+((N37*I37)/100) -> 22472763 | P37: =H37 -> 22710129 | Q37: =-((O37-H37)/H37)*100 -> 1.0451999 | V37: =(O37-P37)/P37 -> -0.010451999
A38: Budha/ | B38: 3.Waisak | C38: Kamis / 23 Mei | D38: 23174758 | E38: 30251429 | F38: 29853482 | G38: 29008794 | H38: 25031136 | I38: 28072116 | J38: -10.832742 | K38: -6.7678605 | L38: -4.0648817 | M38: -3 | N38: =M38+K38 -> -9.7678605 | O38: =I38+((N38*I38)/100) -> 25330071 | P38: =H38 -> 25031136 | Q38: =((O38-H38)/H38)*100 -> 1.1942519 | V38: =(O38-P38)/P38 -> 0.011942519
A39: Tionghoa | P39: MAPE | Q39: =SUM(Q25:Q38)/14 -> 1.5234669 | R39: RMSE | S39: =SQRT(SUMSQ(Q25:Q38)/COUNTA(Q25:Q38)) -> 2.0225449 | T39: R2 | U39: =RSQ(O25:O38,P25:P38) -> 0.93174223 | V39: MAE | W39: {=AVERAGE(ABS(V25:V38))} -> 0.015234669
A41: Forecasting menggunakan Fuzzytype2-CSA
A42: Kelompok | B42: Nama Hari Libur | C42: Hari | D42: Hari Ke | I42: WDMAX | J42: LDMAX | K42: TLDMAX | L42: VLDMAX | M42: Output | N42: Forecast | O42: Peramalan | P42: Aktual | Q42: Error
C43: Tanggal | D43: H-4 | E43: H-3 | F43: H-2 | G43: H-1 | H43: H | M43: Forecast | N43: LDMAX | O43: P'MAX(Watthours) | P43: (Watthours) | Q43: (%)
...

Sheet hasil VLD 2024
B2: Type-1 | E2: IT2-FIS | H2: IT2FIS-CSA | K2: IT2FIS-FA | N2: IT2FIS-ZOA | Q2: IT2FIS-OOA
B3: Actual | C3: Forecast | D3: Error | E3: Actual | F3: Forecast | G3: Error | H3: Actual | I3: Forecast | J3: Error | K3: Actual | L3: Forecast | M3: Error | N3: Actual | O3: Forecast | P3: Error | Q3: Actual | R3: Forecast | S3: Error
B4: -9.9619177 | C4: -6.8007 | D4: 3.8537772 | E4: -9.9619177 | F4: -6.4974 | G4: 4.2235241 | H4: -9.9619177 | I4: -6.4407 | J4: 4.292646 | K4: -9.9619177 | L4: -6.4047 | M4: 4.3365328 | N4: -9.9619177 | O4: -6.4359 | P4: 4.2984975 | Q4: -9.9619177 | R4: -6.4724 | S4: 4.2540011
B5: -3.6051464 | C5: -3 | D5: 0.67890256 | E5: -3.6051464 | F5: -3 | G5: 0.67890256 | H5: -3.6051464 | I5: -3.0582 | J5: 0.61360906 | K5: -3.6051464 | L5: -3.0472 | M5: 0.62594976 | N5: -3.6051464 | O5: -3.0521 | P5: 0.62045254 | Q5: -3.6051464 | R5: -3.0717 | S5: 0.59846366
B6: -8.5739194 | C6: -9 | D6: 0.52106689 | E6: -8.5739194 | F6: -9 | G6: 0.52106689 | H6: -8.5739194 | I6: -8.9332 | J6: 0.43937514 | K6: -8.5739194 | L6: -8.9253 | M6: 0.42971398 | N6: -8.5739194 | O6: -8.8911 | P6: 0.38788976 | Q6: -8.5739194 | R6: -8.891 | S6: 0.38776747
B7: -3.7454598 | C7: -3 | D7: 0.8097972 | E7: -3.7454598 | F7: -3 | G7: 0.8097972 | H7: -3.7454598 | I7: -3.0625 | J7: 0.7419031 | K7: -3.7454598 | L7: -3.0484 | M7: 0.75722001 | N7: -3.7454598 | O7: -3.052 | P7: 0.75330931 | Q7: -3.7454598 | R7: -3.0723 | S7: 0.7312573
B8: -4.421208 | C8: -6.4094 | D8: 2.2556275 | E8: -4.421208 | F8: -6.2593 | G8: 2.0853373 | H8: -4.421208 | I8: -6.2173 | J8: 2.0376878 | K8: -4.421208 | L8: -6.1835 | M8: 1.9993413 | N8: -4.421208 | O8: -6.2006 | P8: 2.0187414 | Q8: -4.421208 | R8: -6.2414 | S8: 2.0650295
B9: -11.998988 | C9: -12 | D9: 0.0011914375 | E9: -11.998988 | F9: -12 | G9: 0.0011914375 | H9: -11.998988 | I9: -12 | J9: 0.0011914375 | K9: -11.998988 | L9: -12 | M9: 0.0011914375 | N9: -11.998988 | O9: -12 | P9: 0.0011914375 | Q9: -11.998988 | R9: -12 | S9: 0.0011914375
B10: -10.51029 | C10: -12 | D10: 1.8385187 | E10: -10.51029 | F10: -12 | G10: 1.8385187 | H10: -10.51029 | I10: -11.9101 | J10: 1.727569 | K10: -10.51029 | L10: -11.9426 | M10: 1.7676788 | N10: -10.51029 | O10: -11.8953 | P10: 1.7093037 | Q10: -10.51029 | R10: -11.8956 | S10: 1.7096739
B11: -6.4495908 | C11: -6 | D11: 0.49433214 | E11: -6.4495908 | F11: -6 | G11: 0.49433214 | H11: -6.4495908 | I11: -6.0701 | J11: 0.41725609 | K11: -6.4495908 | L11: -6 | M11: 0.49433214 | N11: -6.4495908 | O11: -6 | P11: 0.49433214 | Q11: -6.4495908 | R11: -6 | S11: 0.49433214
B12: -8.8817713 | C12: -9.426 | D12: 0.67483048 | E12: -8.8817713 | F12: -9.8281 | G12: 1.1734248 | H12: -8.8817713 | I12: -9.7744 | J12: 1.1068381 | K12: -8.8817713 | L12: -9.7715 | M12: 1.1032422 | N12: -8.8817713 | O12: -9.6978 | P12: 1.0118559 | Q12: -8.8817713 | R12: -9.6973 | S12: 1.011236
B13: -3.5312117 | C13: -3 | D13: 0.60222942 | E13: -3.5312117 | F13: -3 | G13: 0.60222942 | H13: -3.5312117 | I13: -3.0601 | J13: 0.53409464 | K13: -3.5312117 | L13: -3.047 | M13: 0.54894598 | N13: -3.5312117 | O13: -3.0472 | P13: 0.54871924 | Q13: -3.5312117 | R13: -3.075 | S13: 0.51720266
B14: -4.3427803 | C14: -6 | D14: 1.9833486 | E14: -4.3427803 | F14: -6 | G14: 1.9833486 | H14: -4.3427803 | I14: -5.5481 | J14: 1.4425179 | K14: -4.3427803 | L14: -5.5481 | M14: 1.4425179 | N14: -4.3427803 | O14: -5.5481 | P14: 1.4425179 | Q14: -4.3427803 | R14: -5.5481 | S14: 1.4425179
B15: -13.383836 | C15: -9.0389 | D15: 5.2689492 | E15: -13.383836 | F15: -9.5267 | G15: 4.6774115 | H15: -13.383836 | I15: -9.502 | J15: 4.7073643 | K15: -13.383836 | L15: -9.4698 | M15: 4.7464121 | N15: -13.383836 | O15: -9.463 | P15: 4.7546582 | Q15: -13.383836 | R15: -9.4674 | S15: 4.7493225
... B17: -4.0648817 | C17: -3 | D17: 1.1942519 | E17: -4.0648817 | F17: -3 | G17: 1.1942519 | H17: -4.0648817 | I17: -3.064 | J17: 1.1224767 | K17: -4.0648817 | L17: -3.0476 | M17: 1.1408691 | N17: -4.0648817 | O17: -3.0492 | P17: 1.1390747 | Q17: -4.0648817 | R17: -3.0716 | S17: 1.1139534
B18: MAPE | D18: 1.5158588 | E18: MAPE | G18: 1.5234669 | H18: MAPE | J18: 1.4449807 | K18: MAPE | M18: 1.4599391 | N18: MAPE | P18: 1.444696 | Q18: MAPE | S18: 1.4372249

Sheet VLD(x,y,z)2023
A1: Pembuatan tabel input (X,Y) dan output (Z) berdasarkan VLDMAX tahun 2023
A3: Kelompok | B3: Nama Hari Libur | C3: Hari | D3: 2022 | E3: 2023 | F3: Input | H3: Output
C4: Tanggal | D4: VLDMAX | E4: VLDMAX | F4: X | G4: Y | H4: Z
A5: Hari Libur | B5: 1.Tahun Baru Masehi | C5: Selasa / 01 Januari | D5: ='2022a'!L5 -> -0.48006314 | E5: ='2023a'!L6 -> -11.285594 | F5: =D5 -> -0.48006314 | G5: =E6 -> -9.2225478 | H5: =E5 -> -11.285594
A6: Umum | B6: 2.Proklamasi Kemerdekaan RI | C6: Minggu / 17 Agustus | D6: ='2022a'!L6 -> -6.094273 | E6: ='2023a'!L7 -> -9.2225478 | F6: =D6 -> -6.094273 | G6: =E5 -> -11.285594 | H6: =E6 -> -9.2225478
A7: Hari Raya | B7: 1.Idul Adha | C7: Senin / 08 Desember | D7: ='2022a'!L7 -> -9.9893364 | E7: ='2023a'!L8 -> -13.704771 | F7: =D7 -> -9.9893364 | G7: =E12 -> -1.5371636 | H7: =E7 -> -13.704771
A8: Islam | B8: 2.Tahun Baru Hijriyah | C8: Kamis / 10 Januari | D8: ='2022a'!L8 -> -11.538678 | E8: ='2023a'!L9 -> -10.053036 | F8: =D8 -> -11.538678 | G8: =E7 -> -13.704771 | H8: =E8 -> -10.053036
B9: 3.Maulid Nabi Muhammad SAW | C9: Kamis / 20 Maret | D9: ='2022a'!L9 -> -10.187522 | E9: ='2023a'!L10 -> -11.667397 | F9: =D9 -> -10.187522 | G9: =E8 -> -10.053036 | H9: =E9 -> -11.667397
B10: 4.Isra Mi'raj | C10: Rabu / 30 Juli | D10: ='2022a'!L10 -> -4.6052368 | E10: ='2023a'!L11 -> -3.7583995 | F10: =D10 -> -4.6052368 | G10: =E9 -> -11.667397 | H10: =E10 -> -3.7583995
B11: 5.Idul Fitri I | C11: Rabu / 01 Oktober | D11: ='2022a'!L11 -> -9.8900317 | E11: ='2023a'!L12 -> -15.602986 | F11: =D11 -> -9.8900317 | G11: =E10 -> -3.7583995 | H11: =E11 -> -15.602986
B12: 6.Idul Fitri II | C12: Kamis / 02 Oktober | D12: ='2022a'!L12 -> -3.6756394 | E12: ='2023a'!L13 -> -1.5371636 | F12: =D12 -> -3.6756394 | G12: =E11 -> -15.602986 | H12: =E12 -> -1.5371636
A13: Hari Raya | B13: 1.Wafatnya Yesus Kristus | C13: Jumat / 21 Maret | D13: ='2022a'!L13 -> -6.5432734 | E13: ='2023a'!L14 -> -9.4613273 | F13: =D13 -> -6.5432734 | G13: =E14 -> -6.7784571 | H13: =E13 -> -9.4613273
A14: Kristen | B14: 2.Kenaikan Yesus Kristus | C14: Kamis / 01 Mei | D14: ='2022a'!L14 -> -6.8268972 | E14: ='2023a'!L15 -> -6.7784571 | F14: =D14 -> -6.8268972 | G14: =E13 -> -9.4613273 | H14: =E14 -> -6.7784571
B15: 3.Natal | C15: Kamis / 25 Desember | D15: ='2022a'!L15 -> -4.0278267 | E15: ='2023a'!L16 -> -13.272881 | F15: =D15 -> -4.0278267 | G15: =E14 -> -6.7784571 | H15: =E15 -> -13.272881
A16: Hari Raya | B16: 1.Nyepi | C16: Jumat / 07 Maret | D16: ='2022a'!L16 -> 13.646953 | E16: ='2023a'!L17 -> -9.6447284 | F16: =D16 -> 13.646953 | G16: =E17 -> -11.306996 | H16: =E16 -> -9.6447284
A17: Hindu / | B17: 2.Tahun Baru Imlek | C17: Kamis / 07 Februari | D17: ='2022a'!L17 -> 9.5011013 | E17: ='2023a'!L18 -> -11.306996 | F17: =D17 -> 9.5011013 | G17: =E16 -> -9.6447284 | H17: =E17 -> -11.306996
A18: Budha/ | B18: 3.Waisak | C18: Selasa / 20 Mei | D18: ='2022a'!L18 -> -6.9784191 | E18: ='2023a'!L19 -> -15.889039 | F18: =D18 -> -6.9784191 | G18: =E17 -> -11.306996 | H18: =E18 -> -15.889039
A19: Tionghoa
A22: Pembentukan Aturan Dasar (Rule Base) Untuk Input X tahun 2023
A24: Kelompok | B24: Nama Hari Libur | C24: Nilai | D24: Derajat Keanggotaan (μ) | O24: Himpunan
C25: X | D25: NVB | E25: NB | F25: NM | G25: NS | H25: NVS | I25: ZE | J25: PVS | K25: PS | L25: PM | M25: PB | N25: PVB | O25: X
A26: Hari Libur | B26: 1.Tahun Baru Masehi | C26: =F5 -> -0.48006314 | H26: =-(C26)/3 -> 0.16002105 | I26: =(C26+3)/3 -> 0.83997895 | O26: ZE
A27: Umum | B27: 2.Proklamasi Kemerdekaan RI | C27: =F6 -> -6.094273 | F27: =(-6-(C27))/3 -> 0.031424345 | G27: =(C27+9)/3 -> 0.96857566 | O27: NS
A28: Hari Raya | B28: 1.Idul Adha | C28: =F7 -> -9.9893364 | E28: =(-9-C28)/3 -> 0.32977879 | F28: =(C28+12)/3 -> 0.67022121 | O28: NM
A29: Islam | B29: 2.Tahun Baru Hijriyah | C29: =F8 -> -11.538678 | E29: =(-9-C29)/3 -> 0.84622614 | F29: =(C29+12)/3 -> 0.15377386 | O29: NB
B30: 3.Maulid Nabi Muhammad SAW | C30: =F9 -> -10.187522 | E30: =(-9-C30)/3 -> 0.39584076 | F30: =(C30+12)/3 -> 0.60415924 | O30: NM
B31: 4.Isra Mi'raj | C31: =F10 -> -4.6052368 | F31: =(C30+12)/3 -> 0.60415924 | G31: =(-3-C31)/3 -> 0.53507894 | O31: NM
B32: 5.Idul Fitri I | C32: =F11 -> -9.8900317 | E32: =(-9-C32)/3 -> 0.29667724 | F32: =(C32+12)/3 -> 0.70332276 | O32: NM
B33: 6.Idul Fitri II | C33: =F12 -> -3.6756394 | G33: =(-3-C33)/3 -> 0.22521314 | H33: =(C33+6)/3 -> 0.77478686 | O33: NVS
A34: Hari Raya | B34: 1.Wafatnya Yesus Kristus | C34: =F13 -> -6.5432734 | F34: =(-6-C34)/3 -> 0.18109114 | G34: =(C34+9)/3 -> 0.81890886 | O34: NS
A35: Kristen | B35: 2.Kenaikan Yesus Kristus | C35: =F14 -> -6.8268972 | F35: =(-6-C35)/3 -> 0.2756324 | G35: =(C35+9)/3 -> 0.7243676 | O35: NS
B36: 3.Natal | C36: =F15 -> -4.0278267 | G36: =(-3-C36)/3 -> 0.3426089 | H36: =(C36+6)/3 -> 0.6573911 | O36: NVS
A37: Hari Raya | B37: 1.Nyepi | C37: =F16 -> 13.646953 | M37: =(15-C37)/3 -> 0.45101568 | N37: =(C37-12)/3 -> 0.54898432 | O37: PVB
A38: Hindu / | B38: 1.Tahun Baru Imlek | C38: =F17 -> 9.5011013 | L38: =(12-C38)/3 -> 0.83296623 | M38: =(C38-9)/3 -> 0.16703377 | O38: PM
A39: Budha/ | B39: 2.Waisak | C39: =F18 -> -6.9784191 | F39: =(-6-C39)/3 -> 0.32613971 | G39: =(C39+9)/3 -> 0.67386029 | O39: NS
A40: Tionghoa | C40: =F19 -> 0
A43: Pembentukan Aturan Dasar Untuk Input Y tahun 2023
A45: Kelompok | B45: Nama Hari Libur | C45: Nilai | D45: Derajat Keanggotaan (μ) | O45: Himpunan
C46: Y | D46: NVB | E46: NB | F46: NM | G46: NS | H46: NVS | I46: ZE | J46: PVS | K46: PS | L46: PM | M46: PB | N46: PVB | O46: Y
A47: Hari Libur | B47: 1.Tahun Baru Masehi | C47: -9.2225478 | E47: =(-9-C47)/3 -> 0.074182612 | F47: =(C47+12)/3 -> 0.92581739 | O47: NM
...

Sheet VLD(x,y,z)2024
A1: Pembuatan tabel input (X,Y) dan output (Z) berdasarkan VLDMAX tahun 2024
A3: Kelompok | B3: Nama Hari Libur | C3: Hari | D3: 2023 | E3: 2024 | F3: Input | H3: Output
C4: Tanggal | D4: VLDMAX | E4: VLDMAX | F4: X | G4: Y | H4: Z
A5: Hari Libur | B5: 1.Tahun Baru Masehi | C5: Selasa / 01 Januari | D5: -11.285594 | E5: -9.9619177 | F5: =D5 -> -11.285594 | G5: =E6 -> -3.6051464 | H5: =E5 -> -9.9619177
A6: Umum | B6: 2.Proklamasi Kemerdekaan RI | C6: Minggu / 17 Agustus | D6: -9.2225478 | E6: -3.6051464 | F6: =D6 -> -9.2225478 | G6: =E5 -> -9.9619177 | H6: =E6 -> -3.6051464
A7: Hari Raya | B7: 1.Idul Adha | C7: Senin / 08 Desember | D7: -13.704771 | E7: -8.5739194 | F7: =D7 -> -13.704771 | G7: =E12 -> -6.4495908 | H7: =E7 -> -8.5739194
A8: Islam | B8: 2.Tahun Baru Hijriyah | C8: Kamis / 10 Januari | D8: -10.053036 | E8: -3.7454598 | F8: =D8 -> -10.053036 | G8: =E7 -> -8.5739194 | H8: =E8 -> -3.7454598
B9: 3.Maulid Nabi Muhammad SAW | C9: Kamis / 20 Maret | D9: -11.667397 | E9: -4.421208 | F9: =D9 -> -11.667397 | G9: =E8 -> -3.7454598 | H9: =E9 -> -4.421208
B10: 4.Isra Mi'raj | C10: Rabu / 30 Juli | D10: -3.7583995 | E10: -11.998988 | F10: =D10 -> -3.7583995 | G10: =E9 -> -4.421208 | H10: =E10 -> -11.998988
B11: 5.Idul Fitri I | C11: Rabu / 01 Oktober | D11: -15.602986 | E11: -10.51029 | F11: =D11 -> -15.602986 | G11: =E10 -> -11.998988 | H11: =E11 -> -10.51029
B12: 6.Idul Fitri II | C12: Kamis / 02 Oktober | D12: -1.5371636 | E12: -6.4495908 | F12: =D12 -> -1.5371636 | G12: =E11 -> -10.51029 | H12: =E12 -> -6.4495908
A13: Hari Raya | B13: 1.Wafatnya Yesus Kristus | C13: Jumat / 21 Maret | D13: -9.4613273 | E13: -8.8817713 | F13: =D13 -> -9.4613273 | G13: =E14 -> -3.5312117 | H13: =E13 -> -8.8817713
A14: Kristen | B14: 2.Kenaikan Yesus Kristus | C14: Kamis / 01 Mei | D14: -6.7784571 | E14: -3.5312117 | F14: =D14 -> -6.7784571 | G14: =E13 -> -8.8817713 | H14: =E14 -> -3.5312117
B15: 3.Natal | C15: Kamis / 25 Desember | D15: -13.272881 | E15: -4.3427803 | F15: =D15 -> -13.272881 | G15: =E14 -> -3.5312117 | H15: =E15 -> -4.3427803
A16: Hari Raya | B16: 1.Nyepi | C16: Jumat / 07 Maret | D16: -9.6447284 | E16: -13.383836 | F16: =D16 -> -9.6447284 | G16: =E17 -> -2.1310256 | H16: =E16 -> -13.383836
A17: Hindu / | B17: 2.Tahun Baru Imlek | C17: Kamis / 07 Februari | D17: -11.306996 | E17: -2.1310256 | F17: =D17 -> -11.306996 | G17: =E16 -> -13.383836 | H17: =E17 -> -2.1310256
A18: Budha/ | B18: 3.Waisak | C18: Selasa / 20 Mei | D18: -15.889039 | E18: -4.0648817 | F18: =D18 -> -15.889039 | G18: =E17 -> -2.1310256 | H18: =E18 -> -4.0648817
A19: Tionghoa
A22: Pembentukan Aturan Dasar (Rule Base) Untuk Input X tahun 2024
A24: Kelompok | B24: Nama Hari Libur | C24: Nilai | D24: Derajat Keanggotaan (μ) | O24: Himpunan
C25: X | D25: NVB | E25: NB | F25: NM | G25: NS | H25: NVS | I25: ZE | J25: PVS | K25: PS | L25: PM | M25: PB | N25: PVB | O25: X
A26: Hari Libur | B26: 1.Tahun Baru Masehi | C26: =F5 -> -11.285594 | E26: =(-9-C26)/3 -> 0.76186478 | F26: =(C26+12)/3 -> 0.23813522 | O26: NB
A27: Umum | B27: 2.Proklamasi Kemerdekaan RI | C27: =F6 -> -9.2225478 | E27: =(-9-C27)/3 -> 0.074182612 | F27: =(C27+12)/3 -> 0.92581739 | O27: NM
A28: Hari Raya | B28: 1.Idul Adha | C28: =F7 -> -13.704771 | D28: =(-12-C28)/3 -> 0.56825707 | E28: =(C28+15)/3 -> 0.43174293 | O28: NVB
A29: Islam | B29: 2.Tahun Baru Hijriyah | C29: =F8 -> -10.053036 | E29: =(-9-C29)/3 -> 0.35101193 | F29: =(C29+12)/3 -> 0.64898807 | O29: NM
B30: 3.Maulid Nabi Muhammad SAW | C30: =F9 -> -11.667397 | E30: =(-9-C30)/3 -> 0.8891323 | F30: =(C30+12)/3 -> 0.1108677 | O30: NB
B31: 4.Isra Mi'raj | C31: =F10 -> -3.7583995 | G31: =(-3-C31)/3 -> 0.25279982 | H31: =(C31+6)/3 -> 0.74720018 | O31: NVS
B32: 5.Idul Fitri I | C32: =F11 -> -15.602986 | D32: 1 | O32: NVB
B33: 6.Idul Fitri II | C33: =F12 -> -1.5371636 | H33: =(-(C33))/3 -> 0.51238788 | I33: =(C33+3)/3 -> 0.48761212 | O33: NVS
A34: Hari Raya | B34: 1.Wafatnya Yesus Kristus | C34: =F13 -> -9.4613273 | E34: =(-9-C34)/3 -> 0.15377576 | F34: =(C34+12)/3 -> 0.84622424 | O34: NM
A35: Kristen | B35: 2.Kenaikan Yesus Kristus | C35: =F14 -> -6.7784571 | F35: =(-6-C35)/3 -> 0.2594857 | G35: =(C35+9)/3 -> 0.7405143 | O35: NS
B36: 3.Natal | C36: =F15 -> -13.272881 | D36: =(-12-C36)/3 -> 0.42429377 | E36: =(C36+15)/3 -> 0.57570623 | O36: NB
A37: Hari Raya | B37: 1.Nyepi | C37: =F16 -> -9.6447284 | E37: =(-9-C37)/3 -> 0.21490948 | F37: =(C37+12)/3 -> 0.78509052 | O37: NM
A38: Hindu / | B38: 1.Tahun Baru Imlek | C38: =F17 -> -11.306996 | E38: =(-9-C38)/3 -> 0.76899868 | F38: =(C38+12)/3 -> 0.23100132 | O38: NB
A39: Budha/ | B39: 2.Waisak | C39: =F18 -> -15.889039 | D39: 1 | O39: NVB
A40: Tionghoa
A43: Pembentukan Aturan Dasar Untuk Input Y tahun 2024
A45: Kelompok | B45: Nama Hari Libur | C45: Nilai | D45: Derajat Keanggotaan (μ) | O45: Himpunan
C46: Y | D46: NVB | E46: NB | F46: NM | G46: NS | H46: NVS | I46: ZE | J46: PVS | K46: PS | L46: PM | M46: PB | N46: PVB | O46: Y
A47: Hari Libur | B47: 1.Tahun Baru Masehi | C47: =G5 -> -3.6051464 | G47: =(-3-C47)/3 -> 0.20171548 | H47: =(C47+6)/3 -> 0.79828452 | O47: NVS
...

Sheet RuleBase 2023
A2: Tabel rules base untuk tahun peramalan tahun 2023
B3: 1 | C3: 2 | D3: 3 | E3: 4 | F3: 5 | G3: 6 | H3: 7 | I3: 8 | J3: 9 | K3: 10 | L3: 11
A4: X/Y | B4: NVB | C4: NB | D4: NM | E4: NS | F4: NVS | G4: ZE | H4: PVS | I4: PS | J4: PM | K4: PB | L4: PVB
A5: NVB
A6: NB
A7: NM
A8: NS
A9: NVS
A10: ZE | D10: NB
A11: PVS
A12: PS
A13: PM
A14: PB
A15: PVB
A17: No. | B17: Antecendent | D17: Consequen | F17: No. | G17: Antecendent | I17: Consequen
A18: Aturan | B18: X | C18: Y | D18: Z | F18: Aturan | G18: X | H18: Y | I18: Z
A19: 1 | B19: ZE | C19: NM | D19: NB | F19: 1 | G19: 6 | H19: 3 | I19: 2
A20: 2 | B20: NS | C20: NB | D20: NM | F20: 2 | G20: 4 | H20: 2 | I20: 3
A21: 3 | B21: NM | C21: NVS | D21: NVB | F21: 3 | G21: 3 | H21: 5 | I21: 1
A22: 4 | B22: NB | C22: NVB | D22: NM | F22: 4 | G22: 2 | H22: 1 | I22: 3
A23: 5 | B23: NM | C23: NM | D23: NB | F23: 5 | G23: 3 | H23: 3 | I23: 2
A24: 6 | B24: NM | C24: NB | D24: NVS | F24: 6 | G24: 3 | H24: 2 | I24: 5
A25: 7 | B25: NM | C25: NVS | D25: NVB | F25: 7 | G25: 3 | H25: 5 | I25: 1
A26: 8 | B26: NVS | C26: NVB | D26: NVS | F26: 8 | G26: 5 | H26: 1 | I26: 5
A27: 9 | B27: NS | C27: NS | D27: NM | F27: 9 | G27: 4 | H27: 4 | I27: 3
A28: 10 | B28: NS | C28: NM | D28: NS | F28: 10 | G28: 4 | H28: 3 | I28: 4
A29: 11 | B29: NVS | C29: NS | D29: NB | F29: 11 | G29: 5 | H29: 4 | I29: 2
